Workbook

Sheet 📋 Instructions
B2: VMware vCenter 8 – Capacity Planning Template
B4: Version 1.0 | Généré le 23/03/2026 | Compatible vCenter 8.x
B6: 🗂️ STRUCTURE DU CLASSEUR
B8: Onglet | C8: Description | D8: Source
B9: 📋 Instructions | C9: Ce guide d'utilisation du template | D9: —
B10: 🖥️ RAW_Hosts | C10: Coller ici l'export vCenter des ESXi hosts | D10: vCenter > Hosts & Clusters > Export CSV
B11: 💾 RAW_Datastores | C11: Coller ici l'export vCenter des datastores | D11: vCenter > Storage > Export CSV
B12: ⚡ RAW_VMs | C12: Coller ici l'export vCenter des VMs | D12: vCenter > VMs > Export CSV
B13: 📊 Capacity_Hosts | C13: Analyse automatique CPU/RAM par cluster | D13: Alimenté par RAW_Hosts
B14: 💽 Capacity_Storage | C14: Analyse automatique stockage par datastore | D14: Alimenté par RAW_Datastores
B15: 🔮 Projections | C15: Projections de croissance sur 12 mois | D15: Paramètres modifiables
B16: 📈 Dashboard | C16: Tableaux de bord visuels et KPIs | D16: Vue consolidée
B18: 📥 IMPORTS VCENTER 8 – CHAMPS REQUIS
B19: 🖥️ HOSTS
C20: • Host
C21: • Cluster
C22: • CPU Sockets
C23: • CPU Cores per Socket
C24: • CPU Usage MHz
C25: • CPU Total MHz
C26: • Memory Usage MB
C27: • Memory Total MB
C28: • State
C29: • Version
B30: 💾 DATASTORES
C31: • Datastore
C32: • Type (VMFS/NFS/vSAN)
C33: • Capacity GB
C34: • Free Space GB
C35: • Provisioned GB
C36: • Accessible
C37: • Hosts
B38: ⚡ VMs
C39: • VM Name
C40: • Power State
C41: • Host
C42: • Cluster
C43: • CPUs
C44: • Memory MB
C45: • Provisioned Storage GB
...

Sheet 🖥️ RAW_Hosts
A1: 🖥️ DONNÉES HOSTS ESXI – Export vCenter 8
A2: Host Name | B2: Cluster | C2: CPU Sockets | D2: Cores/Socket | E2: Total vCPUs | F2: CPU Usage (MHz) | G2: CPU Total (MHz) | H2: CPU Usage % | I2: Mem Usage (MB) | J2: Mem Total (MB) | K2: Mem Usage % | L2: VMs Count | M2: State | N2: ESXi Version | O2: Notes
A3: esxi-01.lab.local | B3: PROD-Cluster-01 | C3: 2 | D3: 20 | E3: =C3*D3 | F3: 18500 | G3: 80000 | H3: =IFERROR(F3/G3,0) | I3: 245760 | J3: 393216 | K3: =IFERROR(I3/J3,0) | L3: 12 | M3: Connected | N3: 8.0.2
A4: esxi-02.lab.local | B4: PROD-Cluster-01 | C4: 2 | D4: 20 | E4: =C4*D4 | F4: 22000 | G4: 80000 | H4: =IFERROR(F4/G4,0) | I4: 310000 | J4: 393216 | K4: =IFERROR(I4/J4,0) | L4: 15 | M4: Connected | N4: 8.0.2
A5: esxi-03.lab.local | B5: PROD-Cluster-01 | C5: 2 | D5: 20 | E5: =C5*D5 | F5: 15200 | G5: 80000 | H5: =IFERROR(F5/G5,0) | I5: 200000 | J5: 393216 | K5: =IFERROR(I5/J5,0) | L5: 10 | M5: Connected | N5: 8.0.2
A6: esxi-04.lab.local | B6: PROD-Cluster-02 | C6: 2 | D6: 16 | E6: =C6*D6 | F6: 32000 | G6: 64000 | H6: =IFERROR(F6/G6,0) | I6: 180000 | J6: 262144 | K6: =IFERROR(I6/J6,0) | L6: 8 | M6: Connected | N6: 8.0.1
A7: esxi-05.lab.local | B7: PROD-Cluster-02 | C7: 2 | D7: 16 | E7: =C7*D7 | F7: 28000 | G7: 64000 | H7: =IFERROR(F7/G7,0) | I7: 195000 | J7: 262144 | K7: =IFERROR(I7/J7,0) | L7: 9 | M7: Connected | N7: 8.0.1
A8: esxi-06.lab.local | B8: DEV-Cluster-01 | C8: 2 | D8: 12 | E8: =C8*D8 | F8: 8000 | G8: 48000 | H8: =IFERROR(F8/G8,0) | I8: 80000 | J8: 196608 | K8: =IFERROR(I8/J8,0) | L8: 6 | M8: Connected | N8: 8.0.2
A9: esxi-07.lab.local | B9: DEV-Cluster-01 | C9: 2 | D9: 12 | E9: =C9*D9 | F9: 5000 | G9: 48000 | H9: =IFERROR(F9/G9,0) | I9: 60000 | J9: 196608 | K9: =IFERROR(I9/J9,0) | L9: 4 | M9: Connected | N9: 8.0.2

Sheet 💾 RAW_Datastores
A1: 💾 DONNÉES DATASTORES – Export vCenter 8
A2: Datastore Name | B2: Type | C2: Cluster/Host | D2: Capacity (GB) | E2: Free Space (GB) | F2: Used (GB) | G2: Usage % | H2: Provisioned (GB) | I2: Over-Commit % | J2: Accessible | K2: VMs | L2: Notes
A3: PROD-DS-SAN-01 | B3: VMFS | C3: PROD-Cluster-01 | D3: 10240 | E3: 2800 | F3: =D3-E3 | G3: =IFERROR(F3/D3,0) | H3: 12500 | I3: =IFERROR(H3/D3,0) | J3: Yes | K3: 18
A4: PROD-DS-SAN-02 | B4: VMFS | C4: PROD-Cluster-01 | D4: 10240 | E4: 1200 | F4: =D4-E4 | G4: =IFERROR(F4/D4,0) | H4: 14000 | I4: =IFERROR(H4/D4,0) | J4: Yes | K4: 22
A5: PROD-DS-NFS-01 | B5: NFS | C5: PROD-Cluster-01 | D5: 5120 | E5: 1800 | F5: =D5-E5 | G5: =IFERROR(F5/D5,0) | H5: 4500 | I5: =IFERROR(H5/D5,0) | J5: Yes | K5: 8
A6: PROD-DS-SAN-03 | B6: VMFS | C6: PROD-Cluster-02 | D6: 8192 | E6: 3500 | F6: =D6-E6 | G6: =IFERROR(F6/D6,0) | H6: 7000 | I6: =IFERROR(H6/D6,0) | J6: Yes | K6: 14
A7: PROD-DS-SAN-04 | B7: VMFS | C7: PROD-Cluster-02 | D7: 8192 | E7: 500 | F7: =D7-E7 | G7: =IFERROR(F7/D7,0) | H7: 10000 | I7: =IFERROR(H7/D7,0) | J7: Yes | K7: 16
A8: DEV-DS-NFS-01 | B8: NFS | C8: DEV-Cluster-01 | D8: 4096 | E8: 2100 | F8: =D8-E8 | G8: =IFERROR(F8/D8,0) | H8: 2800 | I8: =IFERROR(H8/D8,0) | J8: Yes | K8: 7
A9: DEV-DS-SAN-01 | B9: VMFS | C9: DEV-Cluster-01 | D9: 2048 | E9: 800 | F9: =D9-E9 | G9: =IFERROR(F9/D9,0) | H9: 1800 | I9: =IFERROR(H9/D9,0) | J9: Yes | K9: 5
A10: ARCHIVE-DS-01 | B10: NFS | C10: DEV-Cluster-01 | D10: 20480 | E10: 8000 | F10: =D10-E10 | G10: =IFERROR(F10/D10,0) | H10: 15000 | I10: =IFERROR(H10/D10,0) | J10: Yes | K10: 3

Sheet ⚡ RAW_VMs
A1: ⚡ DONNÉES MACHINES VIRTUELLES – Export vCenter 8
A2: VM Name | B2: Power State | C2: Host | D2: Cluster | E2: vCPUs | F2: Memory (MB) | G2: Memory (GB) | H2: Prov. Storage (GB) | I2: Used Storage (GB) | J2: Guest OS | K2: VMware Tools | L2: CPU Usage % | M2: Notes
A3: vm-web-prod-01 | B3: poweredOn | C3: esxi-01.lab.local | D3: PROD-Cluster-01 | E3: 4 | F3: 16384 | G3: =F3/1024 | H3: 120 | I3: 85 | J3: Ubuntu 22.04 | K3: Current | L3: 35%
A4: vm-db-prod-01 | B4: poweredOn | C4: esxi-01.lab.local | D4: PROD-Cluster-01 | E4: 8 | F4: 65536 | G4: =F4/1024 | H4: 500 | I4: 420 | J4: RHEL 9 | K4: Current | L4: 62%
A5: vm-app-prod-01 | B5: poweredOn | C5: esxi-02.lab.local | D5: PROD-Cluster-01 | E5: 4 | F5: 32768 | G5: =F5/1024 | H5: 200 | I5: 150 | J5: Windows 2022 | K5: Current | L5: 28%
A6: vm-app-prod-02 | B6: poweredOn | C6: esxi-02.lab.local | D6: PROD-Cluster-01 | E6: 4 | F6: 32768 | G6: =F6/1024 | H6: 200 | I6: 160 | J6: Windows 2022 | K6: Current | L6: 31%
A7: vm-api-prod-01 | B7: poweredOn | C7: esxi-03.lab.local | D7: PROD-Cluster-01 | E7: 2 | F7: 8192 | G7: =F7/1024 | H7: 80 | I7: 55 | J7: Ubuntu 22.04 | K7: Current | L7: 18%
A8: vm-db-prod-02 | B8: poweredOn | C8: esxi-04.lab.local | D8: PROD-Cluster-02 | E8: 8 | F8: 131072 | G8: =F8/1024 | H8: 800 | I8: 650 | J8: Oracle Linux | K8: Current | L8: 75%
A9: vm-erp-prod-01 | B9: poweredOn | C9: esxi-04.lab.local | D9: PROD-Cluster-02 | E9: 16 | F9: 131072 | G9: =F9/1024 | H9: 600 | I9: 520 | J9: Windows 2019 | K9: Current | L9: 55%
A10: vm-backup-prod-01 | B10: poweredOn | C10: esxi-05.lab.local | D10: PROD-Cluster-02 | E10: 4 | F10: 16384 | G10: =F10/1024 | H10: 2000 | I10: 1800 | J10: Windows 2022 | K10: Current | L10: 12%
A11: vm-dev-01 | B11: poweredOn | C11: esxi-06.lab.local | D11: DEV-Cluster-01 | E11: 2 | F11: 8192 | G11: =F11/1024 | H11: 80 | I11: 40 | J11: Ubuntu 22.04 | K11: Current | L11: 8%
A12: vm-dev-02 | B12: poweredOff | C12: esxi-06.lab.local | D12: DEV-Cluster-01 | E12: 4 | F12: 16384 | G12: =F12/1024 | H12: 120 | I12: 100 | J12: Windows 2022 | K12: Current | L12: 0%
A13: vm-test-01 | B13: poweredOn | C13: esxi-07.lab.local | D13: DEV-Cluster-01 | E13: 2 | F13: 4096 | G13: =F13/1024 | H13: 60 | I13: 30 | J13: Ubuntu 20.04 | K13: Outdated | L13: 5%
A14: vm-test-02 | B14: poweredOff | C14: esxi-07.lab.local | D14: DEV-Cluster-01 | E14: 2 | F14: 4096 | G14: =F14/1024 | H14: 60 | I14: 25 | J14: CentOS 7 | K14: Outdated | L14: 0%

Sheet 📊 Capacity_Hosts
A1: 📊 ANALYSE DE CAPACITÉ – COMPUTE (CPU & RAM)
A2: Données issues de l'onglet 🖥️ RAW_Hosts | Mise à jour automatique
A4: 🔢 RÉCAPITULATIF GLOBAL
A5: Total Hosts | D5: Total vCPUs | G5: CPU Utilisé | J5: RAM Totale | M5: RAM Utilisée
A6: =COUNTA('🖥️ RAW_Hosts'!A3:A100)-COUNTBLANK('🖥️ RAW_Hosts'!A3:A100) | D6: =SUM('🖥️ RAW_Hosts'!E3:E100) | G6: =IFERROR(SUM('🖥️ RAW_Hosts'!F3:F100)/SUM('🖥️ RAW_Hosts'!G3:G100),0) | J6: =IFERROR(ROUND(SUM('🖥️ RAW_Hosts'!J3:J100)/1024,0),0) | M6: =IFERROR(SUM('🖥️ RAW_Hosts'!I3:I100)/SUM('🖥️ RAW_Hosts'!J3:J100),0)
A7: hosts | D7: cores logiques | G7: % usage moyen | J7: GB total cluster | M7: % usage moyen
A9: 📋 DÉTAIL PAR HOST
A10: Host Name | B10: Cluster | C10: Tot. vCPUs | D10: CPU Usage(MHz) | E10: CPU Total(MHz) | F10: CPU% | G10: Statut CPU | H10: RAM Usage(MB) | I10: RAM Total(MB) | J10: RAM% | K10: Statut RAM | L10: VMs | M10: Version ESXi | N10: Headroom CPU(MHz) | O10: Headroom RAM(MB)
A11: ='🖥️ RAW_Hosts'!A3 | B11: ='🖥️ RAW_Hosts'!B3 | C11: ='🖥️ RAW_Hosts'!E3 | D11: ='🖥️ RAW_Hosts'!F3 | E11: ='🖥️ RAW_Hosts'!G3 | F11: =IFERROR(D11/E11,0) | G11: =IF(F11<0.7,"✅ OK",IF(F11<0.85,"⚠️ Warning","🔴 Critical")) | H11: ='🖥️ RAW_Hosts'!I3 | I11: ='🖥️ RAW_Hosts'!J3 | J11: =IFERROR(H11/I11,0) | K11: =IF(J11<0.75,"✅ OK",IF(J11<0.90,"⚠️ Warning","🔴 Critical")) | L11: ='🖥️ RAW_Hosts'!L3 | M11: ='🖥️ RAW_Hosts'!N3 | N11: =E11-D11 | O11: =I11-H11
A12: ='🖥️ RAW_Hosts'!A4 | B12: ='🖥️ RAW_Hosts'!B4 | C12: ='🖥️ RAW_Hosts'!E4 | D12: ='🖥️ RAW_Hosts'!F4 | E12: ='🖥️ RAW_Hosts'!G4 | F12: =IFERROR(D12/E12,0) | G12: =IF(F12<0.7,"✅ OK",IF(F12<0.85,"⚠️ Warning","🔴 Critical")) | H12: ='🖥️ RAW_Hosts'!I4 | I12: ='🖥️ RAW_Hosts'!J4 | J12: =IFERROR(H12/I12,0) | K12: =IF(J12<0.75,"✅ OK",IF(J12<0.90,"⚠️ Warning","🔴 Critical")) | L12: ='🖥️ RAW_Hosts'!L4 | M12: ='🖥️ RAW_Hosts'!N4 | N12: =E12-D12 | O12: =I12-H12
A13: ='🖥️ RAW_Hosts'!A5 | B13: ='🖥️ RAW_Hosts'!B5 | C13: ='🖥️ RAW_Hosts'!E5 | D13: ='🖥️ RAW_Hosts'!F5 | E13: ='🖥️ RAW_Hosts'!G5 | F13: =IFERROR(D13/E13,0) | G13: =IF(F13<0.7,"✅ OK",IF(F13<0.85,"⚠️ Warning","🔴 Critical")) | H13: ='🖥️ RAW_Hosts'!I5 | I13: ='🖥️ RAW_Hosts'!J5 | J13: =IFERROR(H13/I13,0) | K13: =IF(J13<0.75,"✅ OK",IF(J13<0.90,"⚠️ Warning","🔴 Critical")) | L13: ='🖥️ RAW_Hosts'!L5 | M13: ='🖥️ RAW_Hosts'!N5 | N13: =E13-D13 | O13: =I13-H13
A14: ='🖥️ RAW_Hosts'!A6 | B14: ='🖥️ RAW_Hosts'!B6 | C14: ='🖥️ RAW_Hosts'!E6 | D14: ='🖥️ RAW_Hosts'!F6 | E14: ='🖥️ RAW_Hosts'!G6 | F14: =IFERROR(D14/E14,0) | G14: =IF(F14<0.7,"✅ OK",IF(F14<0.85,"⚠️ Warning","🔴 Critical")) | H14: ='🖥️ RAW_Hosts'!I6 | I14: ='🖥️ RAW_Hosts'!J6 | J14: =IFERROR(H14/I14,0) | K14: =IF(J14<0.75,"✅ OK",IF(J14<0.90,"⚠️ Warning","🔴 Critical")) | L14: ='🖥️ RAW_Hosts'!L6 | M14: ='🖥️ RAW_Hosts'!N6 | N14: =E14-D14 | O14: =I14-H14
A15: ='🖥️ RAW_Hosts'!A7 | B15: ='🖥️ RAW_Hosts'!B7 | C15: ='🖥️ RAW_Hosts'!E7 | D15: ='🖥️ RAW_Hosts'!F7 | E15: ='🖥️ RAW_Hosts'!G7 | F15: =IFERROR(D15/E15,0) | G15: =IF(F15<0.7,"✅ OK",IF(F15<0.85,"⚠️ Warning","🔴 Critical")) | H15: ='🖥️ RAW_Hosts'!I7 | I15: ='🖥️ RAW_Hosts'!J7 | J15: =IFERROR(H15/I15,0) | K15: =IF(J15<0.75,"✅ OK",IF(J15<0.90,"⚠️ Warning","🔴 Critical")) | L15: ='🖥️ RAW_Hosts'!L7 | M15: ='🖥️ RAW_Hosts'!N7 | N15: =E15-D15 | O15: =I15-H15
A16: ='🖥️ RAW_Hosts'!A8 | B16: ='🖥️ RAW_Hosts'!B8 | C16: ='🖥️ RAW_Hosts'!E8 | D16: ='🖥️ RAW_Hosts'!F8 | E16: ='🖥️ RAW_Hosts'!G8 | F16: =IFERROR(D16/E16,0) | G16: =IF(F16<0.7,"✅ OK",IF(F16<0.85,"⚠️ Warning","🔴 Critical")) | H16: ='🖥️ RAW_Hosts'!I8 | I16: ='🖥️ RAW_Hosts'!J8 | J16: =IFERROR(H16/I16,0) | K16: =IF(J16<0.75,"✅ OK",IF(J16<0.90,"⚠️ Warning","🔴 Critical")) | L16: ='🖥️ RAW_Hosts'!L8 | M16: ='🖥️ RAW_Hosts'!N8 | N16: =E16-D16 | O16: =I16-H16
A17: ='🖥️ RAW_Hosts'!A9 | B17: ='🖥️ RAW_Hosts'!B9 | C17: ='🖥️ RAW_Hosts'!E9 | D17: ='🖥️ RAW_Hosts'!F9 | E17: ='🖥️ RAW_Hosts'!G9 | F17: =IFERROR(D17/E17,0) | G17: =IF(F17<0.7,"✅ OK",IF(F17<0.85,"⚠️ Warning","🔴 Critical")) | H17: ='🖥️ RAW_Hosts'!I9 | I17: ='🖥️ RAW_Hosts'!J9 | J17: =IFERROR(H17/I17,0) | K17: =IF(J17<0.75,"✅ OK",IF(J17<0.90,"⚠️ Warning","🔴 Critical")) | L17: ='🖥️ RAW_Hosts'!L9 | M17: ='🖥️ RAW_Hosts'!N9 | N17: =E17-D17 | O17: =I17-H17
A18: TOTAUX / MOYENNES | C18: =SUM(C11:C17) | D18: =SUM(D11:D17) | E18: =SUM(E11:E17) | F18: =IFERROR(SUM(D11:D17)/SUM(E11:E17),0) | H18: =SUM(H11:H17) | I18: =SUM(I11:I17) | J18: =IFERROR(SUM(H11:H17)/SUM(I11:I17),0) | L18: =SUM(L11:L17) | N18: =SUM(N11:N17) | O18: =SUM(O11:O17)
A20: 📈 GRAPHIQUES UTILISATION CPU & RAM

Sheet 💽 Capacity_Storage
A1: 💽 ANALYSE DE CAPACITÉ – STOCKAGE
A2: Données issues de l'onglet 💾 RAW_Datastores | Mise à jour automatique
A4: 🔢 RÉCAPITULATIF STOCKAGE
A5: Capacité Totale | D5: Espace Libre | G5: Espace Utilisé | J5: Prov. Total | M5: Over-Commit
A6: =IFERROR(ROUND(SUM('💾 RAW_Datastores'!D3:D100),0),0) | D6: =IFERROR(ROUND(SUM('💾 RAW_Datastores'!E3:E100),0),0) | G6: =IFERROR(SUM('💾 RAW_Datastores'!F3:F100)/SUM('💾 RAW_Datastores'!D3:D100),0) | J6: =IFERROR(ROUND(SUM('💾 RAW_Datastores'!H3:H100),0),0) | M6: =IFERROR(SUM('💾 RAW_Datastores'!H3:H100)/SUM('💾 RAW_Datastores'!D3:D100),0)
A7: GB total | D7: GB disponibles | G7: % usage global | J7: GB provisionnés | M7: ratio global
A9: 📋 DÉTAIL PAR DATASTORE
A10: Datastore | B10: Type | C10: Cluster/Host | D10: Capacity(GB) | E10: Free(GB) | F10: Used(GB) | G10: Usage% | H10: Statut | I10: Prov(GB) | J10: Over-Commit% | K10: VMs | L10: Alerte
A11: ='💾 RAW_Datastores'!A3 | B11: ='💾 RAW_Datastores'!B3 | C11: ='💾 RAW_Datastores'!C3 | D11: ='💾 RAW_Datastores'!D3 | E11: ='💾 RAW_Datastores'!E3 | F11: =D11-E11 | G11: =IFERROR(F11/D11,0) | H11: =IF(G11<0.7,"✅ OK",IF(G11<0.85,"⚠️ Warning","🔴 Critical")) | I11: ='💾 RAW_Datastores'!H3 | J11: =IFERROR(I11/D11,0) | K11: ='💾 RAW_Datastores'!K3 | L11: =IF(J11>1.5,"🔴 Sur-prov élevé",IF(J11>1.2,"⚠️ Surveiller","✅ Normal"))
A12: ='💾 RAW_Datastores'!A4 | B12: ='💾 RAW_Datastores'!B4 | C12: ='💾 RAW_Datastores'!C4 | D12: ='💾 RAW_Datastores'!D4 | E12: ='💾 RAW_Datastores'!E4 | F12: =D12-E12 | G12: =IFERROR(F12/D12,0) | H12: =IF(G12<0.7,"✅ OK",IF(G12<0.85,"⚠️ Warning","🔴 Critical")) | I12: ='💾 RAW_Datastores'!H4 | J12: =IFERROR(I12/D12,0) | K12: ='💾 RAW_Datastores'!K4 | L12: =IF(J12>1.5,"🔴 Sur-prov élevé",IF(J12>1.2,"⚠️ Surveiller","✅ Normal"))
A13: ='💾 RAW_Datastores'!A5 | B13: ='💾 RAW_Datastores'!B5 | C13: ='💾 RAW_Datastores'!C5 | D13: ='💾 RAW_Datastores'!D5 | E13: ='💾 RAW_Datastores'!E5 | F13: =D13-E13 | G13: =IFERROR(F13/D13,0) | H13: =IF(G13<0.7,"✅ OK",IF(G13<0.85,"⚠️ Warning","🔴 Critical")) | I13: ='💾 RAW_Datastores'!H5 | J13: =IFERROR(I13/D13,0) | K13: ='💾 RAW_Datastores'!K5 | L13: =IF(J13>1.5,"🔴 Sur-prov élevé",IF(J13>1.2,"⚠️ Surveiller","✅ Normal"))
A14: ='💾 RAW_Datastores'!A6 | B14: ='💾 RAW_Datastores'!B6 | C14: ='💾 RAW_Datastores'!C6 | D14: ='💾 RAW_Datastores'!D6 | E14: ='💾 RAW_Datastores'!E6 | F14: =D14-E14 | G14: =IFERROR(F14/D14,0) | H14: =IF(G14<0.7,"✅ OK",IF(G14<0.85,"⚠️ Warning","🔴 Critical")) | I14: ='💾 RAW_Datastores'!H6 | J14: =IFERROR(I14/D14,0) | K14: ='💾 RAW_Datastores'!K6 | L14: =IF(J14>1.5,"🔴 Sur-prov élevé",IF(J14>1.2,"⚠️ Surveiller","✅ Normal"))
A15: ='💾 RAW_Datastores'!A7 | B15: ='💾 RAW_Datastores'!B7 | C15: ='💾 RAW_Datastores'!C7 | D15: ='💾 RAW_Datastores'!D7 | E15: ='💾 RAW_Datastores'!E7 | F15: =D15-E15 | G15: =IFERROR(F15/D15,0) | H15: =IF(G15<0.7,"✅ OK",IF(G15<0.85,"⚠️ Warning","🔴 Critical")) | I15: ='💾 RAW_Datastores'!H7 | J15: =IFERROR(I15/D15,0) | K15: ='💾 RAW_Datastores'!K7 | L15: =IF(J15>1.5,"🔴 Sur-prov élevé",IF(J15>1.2,"⚠️ Surveiller","✅ Normal"))
A16: ='💾 RAW_Datastores'!A8 | B16: ='💾 RAW_Datastores'!B8 | C16: ='💾 RAW_Datastores'!C8 | D16: ='💾 RAW_Datastores'!D8 | E16: ='💾 RAW_Datastores'!E8 | F16: =D16-E16 | G16: =IFERROR(F16/D16,0) | H16: =IF(G16<0.7,"✅ OK",IF(G16<0.85,"⚠️ Warning","🔴 Critical")) | I16: ='💾 RAW_Datastores'!H8 | J16: =IFERROR(I16/D16,0) | K16: ='💾 RAW_Datastores'!K8 | L16: =IF(J16>1.5,"🔴 Sur-prov élevé",IF(J16>1.2,"⚠️ Surveiller","✅ Normal"))
A17: ='💾 RAW_Datastores'!A9 | B17: ='💾 RAW_Datastores'!B9 | C17: ='💾 RAW_Datastores'!C9 | D17: ='💾 RAW_Datastores'!D9 | E17: ='💾 RAW_Datastores'!E9 | F17: =D17-E17 | G17: =IFERROR(F17/D17,0) | H17: =IF(G17<0.7,"✅ OK",IF(G17<0.85,"⚠️ Warning","🔴 Critical")) | I17: ='💾 RAW_Datastores'!H9 | J17: =IFERROR(I17/D17,0) | K17: ='💾 RAW_Datastores'!K9 | L17: =IF(J17>1.5,"🔴 Sur-prov élevé",IF(J17>1.2,"⚠️ Surveiller","✅ Normal"))
A18: ='💾 RAW_Datastores'!A10 | B18: ='💾 RAW_Datastores'!B10 | C18: ='💾 RAW_Datastores'!C10 | D18: ='💾 RAW_Datastores'!D10 | E18: ='💾 RAW_Datastores'!E10 | F18: =D18-E18 | G18: =IFERROR(F18/D18,0) | H18: =IF(G18<0.7,"✅ OK",IF(G18<0.85,"⚠️ Warning","🔴 Critical")) | I18: ='💾 RAW_Datastores'!H10 | J18: =IFERROR(I18/D18,0) | K18: ='💾 RAW_Datastores'!K10 | L18: =IF(J18>1.5,"🔴 Sur-prov élevé",IF(J18>1.2,"⚠️ Surveiller","✅ Normal"))
A19: TOTAUX | D19: =SUM(D11:D18) | E19: =SUM(E11:E18) | F19: =SUM(F11:F18) | G19: =IFERROR(SUM(F11:F18)/SUM(D11:D18),0) | I19: =SUM(I11:I18) | K19: =SUM(K11:K18)
A21: 📊 GRAPHIQUES STOCKAGE

Sheet 🔮 Projections
A1: 🔮 PROJECTIONS DE CAPACITÉ – 12 MOIS
A3: ⚙️ PARAMÈTRES DE PROJECTION (cellules bleues = modifiables)
A4: Taux de croissance VM mensuel | B4: 0.05 | C4: ← 5% par mois
A5: Taux de croissance CPU mensuel | B5: 0.04 | C5: ← 4% usage CPU/mois
A6: Taux de croissance RAM mensuel | B6: 0.04 | C6: ← 4% usage RAM/mois
A7: Taux de croissance stockage | B7: 0.06 | C7: ← 6% storage/mois
A8: Seuil alerte CPU (%) | B8: 0.8 | C8: ← Seuil critique CPU
A9: Seuil alerte RAM (%) | B9: 0.85 | C9: ← Seuil critique RAM
A10: Seuil alerte Stockage (%) | B10: 0.85 | C10: ← Seuil critique Stg
A11: Buffer de sécurité (%) | B11: 0.1 | C11: ← Marge de sécurité
A13: 📅 PROJECTION MENSUELLE – 12 MOIS
A14: Indicateur | B14: M0 (Actuel) | C14: M+1 | D14: M+2 | E14: M+3 | F14: M+4 | G14: M+5 | H14: M+6 | I14: M+7 | J14: M+8 | K14: M+9 | L14: M+10 | M14: M+11 | N14: M+12
A15: Nb VMs | B15: =COUNTA('⚡ RAW_VMs'!A3:A200)-COUNTBLANK('⚡ RAW_VMs'!A3:A200) | C15: =B15*(1+B4) | D15: =C15*(1+B4) | E15: =D15*(1+B4) | F15: =E15*(1+B4) | G15: =F15*(1+B4) | H15: =G15*(1+B4) | I15: =H15*(1+B4) | J15: =I15*(1+B4) | K15: =J15*(1+B4) | L15: =K15*(1+B4) | M15: =L15*(1+B4) | N15: =M15*(1+B4)
A16: CPU Usage (MHz) | B16: =SUM('🖥️ RAW_Hosts'!F3:F100) | C16: =B16*(1+B5) | D16: =C16*(1+B5) | E16: =D16*(1+B5) | F16: =E16*(1+B5) | G16: =F16*(1+B5) | H16: =G16*(1+B5) | I16: =H16*(1+B5) | J16: =I16*(1+B5) | K16: =J16*(1+B5) | L16: =K16*(1+B5) | M16: =L16*(1+B5) | N16: =M16*(1+B5)
A17: CPU Total (MHz) | B17: =SUM('🖥️ RAW_Hosts'!G3:G100) | C17: =B17 | D17: =C17 | E17: =D17 | F17: =E17 | G17: =F17 | H17: =G17 | I17: =H17 | J17: =I17 | ... N17: =M17
A18: CPU Usage % | B18: =IFERROR(B16/B17,0) | C18: =IFERROR(C16/C17,0) | D18: =IFERROR(D16/D17,0) | E18: =IFERROR(E16/E17,0) | F18: =IFERROR(F16/F17,0) | G18: =IFERROR(G16/G17,0) | H18: =IFERROR(H16/H17,0) | I18: =IFERROR(I16/I17,0) | ... N18: =IFERROR(N16/N17,0)
A19: Statut CPU | B19: =IF(B18<B8,"✅ OK",IF(B18<0.95,"⚠️ Warning","🔴 Critique")) | C19: =IF(C18<B8,"✅ OK",IF(C18<0.95,"⚠️ Warning","🔴 Critique")) | D19: =IF(D18<B8,"✅ OK",IF(D18<0.95,"⚠️ Warning","🔴 Critique")) | E19: =IF(E18<B8,"✅ OK",IF(E18<0.95,"⚠️ Warning","🔴 Critique")) | F19: =IF(F18<B8,"✅ OK",IF(F18<0.95,"⚠️ Warning","🔴 Critique")) | G19: =IF(G18<B8,"✅ OK",IF(G18<0.95,"⚠️ Warning","🔴 Critique")) | H19: =IF(H18<B8,"✅ OK",IF(H18<0.95,"⚠️ Warning","🔴 Critique")) | I19: =IF(I18<B8,"✅ OK",IF(I18<0.95,"⚠️ Warning","🔴 Critique")) | J19: =IF(J18<B8,"✅ OK",IF(J18<0.95,"⚠️ Warning","🔴 Critique")) | K19: =IF(K18<B8,"✅ OK",IF(K18<0.95,"⚠️ Warning","🔴 Critique")) | L19: =IF(L18<B8,"✅ OK",IF(L18<0.95,"⚠️ Warning","🔴 Critique")) | M19: =IF(M18<B8,"✅ OK",IF(M18<0.95,"⚠️ Warning","🔴 Critique")) | N19: =IF(N18<B8,"✅ OK",IF(N18<0.95,"⚠️ Warning","🔴 Critique"))
A20: RAM Usage (MB) | B20: =SUM('🖥️ RAW_Hosts'!I3:I100) | C20: =B20*(1+B6) | D20: =C20*(1+B6) | E20: =D20*(1+B6) | F20: =E20*(1+B6) | G20: =F20*(1+B6) | H20: =G20*(1+B6) | I20: =H20*(1+B6) | J20: =I20*(1+B6) | K20: =J20*(1+B6) | L20: =K20*(1+B6) | M20: =L20*(1+B6) | N20: =M20*(1+B6)
A21: RAM Total (MB) | B21: =SUM('🖥️ RAW_Hosts'!J3:J100) | C21: =B21 | D21: =C21 | E21: =D21 | F21: =E21 | G21: =F21 | H21: =G21 | I21: =H21 | J21: =I21 | ... N21: =M21
A22: RAM Usage % | B22: =IFERROR(B20/B21,0) | C22: =IFERROR(C20/C21,0) | D22: =IFERROR(D20/D21,0) | E22: =IFERROR(E20/E21,0) | F22: =IFERROR(F20/F21,0) | G22: =IFERROR(G20/G21,0) | H22: =IFERROR(H20/H21,0) | I22: =IFERROR(I20/I21,0) | ... N22: =IFERROR(N20/N21,0)
A23: Statut RAM | B23: =IF(B22<B9,"✅ OK",IF(B22<0.95,"⚠️ Warning","🔴 Critique")) | C23: =IF(C22<B9,"✅ OK",IF(C22<0.95,"⚠️ Warning","🔴 Critique")) | D23: =IF(D22<B9,"✅ OK",IF(D22<0.95,"⚠️ Warning","🔴 Critique")) | E23: =IF(E22<B9,"✅ OK",IF(E22<0.95,"⚠️ Warning","🔴 Critique")) | F23: =IF(F22<B9,"✅ OK",IF(F22<0.95,"⚠️ Warning","🔴 Critique")) | G23: =IF(G22<B9,"✅ OK",IF(G22<0.95,"⚠️ Warning","🔴 Critique")) | H23: =IF(H22<B9,"✅ OK",IF(H22<0.95,"⚠️ Warning","🔴 Critique")) | I23: =IF(I22<B9,"✅ OK",IF(I22<0.95,"⚠️ Warning","🔴 Critique")) | J23: =IF(J22<B9,"✅ OK",IF(J22<0.95,"⚠️ Warning","🔴 Critique")) | K23: =IF(K22<B9,"✅ OK",IF(K22<0.95,"⚠️ Warning","🔴 Critique")) | L23: =IF(L22<B9,"✅ OK",IF(L22<0.95,"⚠️ Warning","🔴 Critique")) | M23: =IF(M22<B9,"✅ OK",IF(M22<0.95,"⚠️ Warning","🔴 Critique")) | N23: =IF(N22<B9,"✅ OK",IF(N22<0.95,"⚠️ Warning","🔴 Critique"))
A24: Stockage Utilisé (GB) | B24: =SUM('💾 RAW_Datastores'!F3:F100) | C24: =B24*(1+B7) | D24: =C24*(1+B7) | E24: =D24*(1+B7) | F24: =E24*(1+B7) | G24: =F24*(1+B7) | H24: =G24*(1+B7) | I24: =H24*(1+B7) | J24: =I24*(1+B7) | K24: =J24*(1+B7) | L24: =K24*(1+B7) | M24: =L24*(1+B7) | N24: =M24*(1+B7)
A25: Stockage Total (GB) | B25: =SUM('💾 RAW_Datastores'!D3:D100) | C25: =B25 | D25: =C25 | E25: =D25 | F25: =E25 | G25: =F25 | H25: =G25 | I25: =H25 | J25: =I25 | ... N25: =M25
A26: Stockage Usage % | B26: =IFERROR(B24/B25,0) | C26: =IFERROR(C24/C25,0) | D26: =IFERROR(D24/D25,0) | E26: =IFERROR(E24/E25,0) | F26: =IFERROR(F24/F25,0) | G26: =IFERROR(G24/G25,0) | H26: =IFERROR(H24/H25,0) | I26: =IFERROR(I24/I25,0) | ... N26: =IFERROR(N24/N25,0)
A27: Statut Stockage | B27: =IF(B26<B10,"✅ OK",IF(B26<0.95,"⚠️ Warning","🔴 Critique")) | C27: =IF(C26<B10,"✅ OK",IF(C26<0.95,"⚠️ Warning","🔴 Critique")) | D27: =IF(D26<B10,"✅ OK",IF(D26<0.95,"⚠️ Warning","🔴 Critique")) | E27: =IF(E26<B10,"✅ OK",IF(E26<0.95,"⚠️ Warning","🔴 Critique")) | F27: =IF(F26<B10,"✅ OK",IF(F26<0.95,"⚠️ Warning","🔴 Critique")) | G27: =IF(G26<B10,"✅ OK",IF(G26<0.95,"⚠️ Warning","🔴 Critique")) | H27: =IF(H26<B10,"✅ OK",IF(H26<0.95,"⚠️ Warning","🔴 Critique")) | I27: =IF(I26<B10,"✅ OK",IF(I26<0.95,"⚠️ Warning","🔴 Critique")) | J27: =IF(J26<B10,"✅ OK",IF(J26<0.95,"⚠️ Warning","🔴 Critique")) | K27: =IF(K26<B10,"✅ OK",IF(K26<0.95,"⚠️ Warning","🔴 Critique")) | L27: =IF(L26<B10,"✅ OK",IF(L26<0.95,"⚠️ Warning","🔴 Critique")) | M27: =IF(M26<B10,"✅ OK",IF(M26<0.95,"⚠️ Warning","🔴 Critique")) | N27: =IF(N26<B10,"✅ OK",IF(N26<0.95,"⚠️ Warning","🔴 Critique"))
A30: 📈 GRAPHIQUES DE PROJECTION

Sheet 📈 Dashboard
B2: 📈 VMWARE CAPACITY PLANNING DASHBOARD
B4: Généré le 23 March 2026 | vCenter 8.x | Template v1.0
B6: 🖥️ COMPUTE
B7: Total Hosts | F7: Total vCPUs | J7: CPU Usage % | N7: RAM Totale | R7: RAM Usage %
B8: =COUNTA('🖥️ RAW_Hosts'!A3:A100)-COUNTBLANK('🖥️ RAW_Hosts'!A3:A100) | F8: =SUM('🖥️ RAW_Hosts'!E3:E100) | J8: =IFERROR(SUM('🖥️ RAW_Hosts'!F3:F100)/SUM('🖥️ RAW_Hosts'!G3:G100),0) | N8: =IFERROR(ROUND(SUM('🖥️ RAW_Hosts'!J3:J100)/1024,0),0) | R8: =IFERROR(SUM('🖥️ RAW_Hosts'!I3:I100)/SUM('🖥️ RAW_Hosts'!J3:J100),0)
B9: hôtes ESXi | F9: cores logiq. | J9: usage moyen | N9: GB cluster | R9: usage moyen
B11: 💽 STOCKAGE & VMs
B12: Total VMs | F12: VMs Power On | J12: Cap. Stockage | N12: Stg. Usage % | R12: Over-Commit Stg.
B13: =COUNTA('⚡ RAW_VMs'!A3:A200)-COUNTBLANK('⚡ RAW_VMs'!A3:A200) | F13: =COUNTIF('⚡ RAW_VMs'!B3:B200,"poweredOn") | J13: =IFERROR(ROUND(SUM('💾 RAW_Datastores'!D3:D100)/1024,1),0) | N13: =IFERROR(SUM('💾 RAW_Datastores'!F3:F100)/SUM('💾 RAW_Datastores'!D3:D100),0) | R13: =IFERROR(SUM('💾 RAW_Datastores'!H3:H100)/SUM('💾 RAW_Datastores'!D3:D100),0)
B14: machines virt. | F14: VMs actives | J14: TB total | N14: usage moyen | R14: ratio global
B16: 🚨 ALERTES & RECOMMANDATIONS
B17: CPU Headroom Global | G17: =IFERROR(TEXT((SUM('🖥️ RAW_Hosts'!G3:G100)-SUM('🖥️ RAW_Hosts'!F3:F100))/1000,"#,##0")&" GHz disponibles","N/A")
B18: RAM Headroom Global | G18: =IFERROR(TEXT(ROUND((SUM('🖥️ RAW_Hosts'!J3:J100)-SUM('🖥️ RAW_Hosts'!I3:I100))/1024,0),"#,##0")&" GB RAM libres","N/A")
B19: Stockage Libre Global | G19: =IFERROR(TEXT(ROUND(SUM('💾 RAW_Datastores'!E3:E100),0),"#,##0")&" GB disponibles","N/A")
B20: VMs Hors-ligne | G20: =IFERROR(TEXT(COUNTIF('⚡ RAW_VMs'!B3:B200,"poweredOff"),"0")&" VMs éteintes","N/A")
B21: Datastores Critiques | G21: =IFERROR(TEXT(COUNTIF('💽 Capacity_Storage'!G11:G18,">0.85"),"0")&" DS > 85% utilisé","N/A")
B23: 📊 VISUALISATIONS GLOBALES
