Workbook

Sheet 📋 Instructions
A1: 📋 VMware vCenter 8 – Capacity Planning Template
A2: Version 2.0 | 23/03/2026 | Colonnes vCenter réelles
A6: 🗂️ STRUCTURE DU CLASSEUR
B7: Onglet | C7: Description | D7: Source de données
B8: 📋 Instructions | C8: Ce guide | D8: —
B9: 🖥️ RAW_Hosts | C9: Coller l'export vCenter des hosts | D9: vCenter > Hosts → Export CSV/Excel
B10: 💾 RAW_Datastores | C10: Coller l'export vCenter des datastores | D10: vCenter > Storage → Export CSV/Excel
B11: ⚡ RAW_VMs | C11: Coller l'export vCenter des VMs | D11: vCenter > VMs → Export CSV/Excel
B12: 📊 Capacity_Hosts | C12: Analyse CPU/RAM par host et cluster | D12: Alimenté par RAW_Hosts
B13: 💽 Capacity_Storage | C13: Analyse stockage par datastore | D13: Alimenté par RAW_Datastores
B14: 🔮 Projections | C14: Projections 12 mois paramétrables | D14: Alimenté par tous les RAW
B15: 📈 Dashboard | C15: KPIs + graphiques consolidés | D15: Vue globale
A17: 📥 COLONNES ATTENDUES PAR ONGLET RAW (coller à partir de A3)
B18: 🖥️ RAW_Hosts
B19: Colonne | C19: Description
B20: Name | C20: Nom du host ESXi
B21: State | C21: connected / disconnected / maintenance
B22: Status | C22: green / yellow / red
B23: ClusterDatacenter | C23: Datacenter du cluster
B24: Cluster | C24: Nom du cluster vSphere
B25: Consumed CPU % | C25: Pourcentage CPU consommé (ex: 45%)
B26: Memory Size (MB) | C26: RAM totale du host en MB
B27: CPUs | C27: Nombre total de vCPUs logiques
B28: CPU Free % | C28: Pourcentage CPU libre (ex: 55%)
B29: CPU free cores | C29: Nombre de cœurs CPU libres
B30: NICs | C30: Nombre de cartes réseau
B31: RAM | C31: RAM consommée / utilisée (MB ou %)
B33: 💾 RAW_Datastores
B34: Colonne | C34: Description
B35: Name | C35: Nom du datastore
B36: Cluster | C36: Cluster auquel il est attaché
B37: Status | C37: green / yellow / red
B38: Type | C38: VMFS / NFS / vSAN / vVol
B39: Datastore cluster | C39: Nom du datastore cluster si applicable
B40: Capacity TB | C40: Capacité totale en TB
B41: Capacity | C41: Capacité totale (autre unité possible)
B42: Free | C42: Espace libre en valeur
B43: FreeSize | C43: Espace libre en GB ou TB
B45: ⚡ RAW_VMs
B46: Colonne | C46: Description
...

Sheet 🖥️ RAW_Hosts
A1: 🖥️ DONNÉES HOSTS ESXi – Export vCenter 8
A2: Coller vos données à partir de la ligne 4 | Ne pas modifier les en-têtes ligne 3
A3: Name | B3: State | C3: Status | D3: ClusterDatacenter | E3: Cluster | F3: Consumed CPU % | G3: Memory Size (MB) | H3: CPUs | I3: CPU Free % | J3: CPU free cores | K3: NICs | L3: RAM
A4: esxi-prod-01.lab | B4: connected | C4: green | D4: DC-Paris | E4: PROD-Cluster-01 | F4: 23% | G4: 393216 | H4: 40 | I4: 77% | J4: 31 | K4: 4 | L4: 91136
A5: esxi-prod-02.lab | B5: connected | C5: green | D5: DC-Paris | E5: PROD-Cluster-01 | F5: 55% | G5: 393216 | H5: 40 | I5: 45% | J5: 18 | K5: 4 | L5: 245760
A6: esxi-prod-03.lab | B6: connected | C6: green | D6: DC-Paris | E6: PROD-Cluster-01 | F6: 39% | G6: 393216 | H6: 40 | I6: 61% | J6: 24 | K6: 4 | L6: 180000
A7: esxi-prod-04.lab | B7: connected | C7: green | D7: DC-Paris | E7: PROD-Cluster-02 | F7: 68% | G7: 262144 | H7: 32 | I7: 32% | J7: 10 | K7: 4 | L7: 220000
A8: esxi-prod-05.lab | B8: connected | C8: yellow | D8: DC-Paris | E8: PROD-Cluster-02 | F8: 81% | G8: 262144 | H8: 32 | I8: 19% | J8: 6 | K8: 4 | L8: 240000
A9: esxi-dev-01.lab | B9: connected | C9: green | D9: DC-Nantes | E9: DEV-Cluster-01 | F9: 18% | G9: 196608 | H9: 24 | I9: 82% | J9: 20 | K9: 2 | L9: 45000
A10: esxi-dev-02.lab | B10: connected | C10: green | D10: DC-Nantes | E10: DEV-Cluster-01 | F10: 12% | G10: 196608 | H10: 24 | I10: 88% | J10: 21 | K10: 2 | L10: 35000

Sheet 💾 RAW_Datastores
A1: 💾 DONNÉES DATASTORES – Export vCenter 8
A2: Coller vos données à partir de la ligne 4 | Ne pas modifier les en-têtes ligne 3
A3: Name | B3: Cluster | C3: Status | D3: Type | E3: Datastore cluster | F3: Capacity TB | G3: Capacity | H3: Free | I3: FreeSize
A4: PROD-DS-SAN-01 | B4: PROD-Cluster-01 | C4: green | D4: VMFS | E4: PROD-DsCluster | F4: 10 | G4: 10240 | H4: 2800 | I4: 2.7
A5: PROD-DS-SAN-02 | B5: PROD-Cluster-01 | C5: yellow | D5: VMFS | E5: PROD-DsCluster | F5: 10 | G5: 10240 | H5: 1100 | I5: 1.1
A6: PROD-DS-NFS-01 | B6: PROD-Cluster-01 | C6: green | D6: NFS | F6: 5 | G6: 5120 | H6: 1800 | I6: 1.8
A7: PROD-DS-SAN-03 | B7: PROD-Cluster-02 | C7: green | D7: VMFS | E7: PROD-DsCluster-2 | F7: 8 | G7: 8192 | H7: 3500 | I7: 3.4
A8: PROD-DS-SAN-04 | B8: PROD-Cluster-02 | C8: red | D8: VMFS | E8: PROD-DsCluster-2 | F8: 8 | G8: 8192 | H8: 400 | I8: 0.4
A9: PROD-DS-VSAN-01 | B9: PROD-Cluster-02 | C9: green | D9: vSAN | F9: 15 | G9: 15360 | H9: 6000 | I9: 5.9
A10: DEV-DS-NFS-01 | B10: DEV-Cluster-01 | C10: green | D10: NFS | F10: 4 | G10: 4096 | H10: 2100 | I10: 2
A11: DEV-DS-SAN-01 | B11: DEV-Cluster-01 | C11: green | D11: VMFS | F11: 2 | G11: 2048 | H11: 800 | I11: 0.8
A12: ARCHIVE-DS-01 | B12: DEV-Cluster-01 | C12: green | D12: NFS | F12: 20 | G12: 20480 | H12: 8000 | I12: 7.8

Sheet ⚡ RAW_VMs
A1: ⚡ DONNÉES VMs – Export vCenter 8
A2: Coller vos données à partir de la ligne 4 | Ne pas modifier les en-têtes ligne 3
A3: Name | B3: State | C3: Status | D3: Host | E3: ClusterDatacenter | F3: Cluster | G3: Provisioned Space | H3: Used Space | I3: Host CPU | J3: Host Mem | K3: Active Memory | L3: CPUs
A4: vm-web-prod-01 | B4: poweredOn | C4: green | D4: esxi-prod-01.lab | E4: DC-Paris | F4: PROD-Cluster-01 | G4: 120 | H4: 85 | I4: 18% | J4: 91136 | K4: 65536 | L4: 4
A5: vm-db-prod-01 | B5: poweredOn | C5: green | D5: esxi-prod-01.lab | E5: DC-Paris | F5: PROD-Cluster-01 | G5: 500 | H5: 420 | I5: 62% | J5: 393216 | K5: 280000 | L5: 8
A6: vm-app-prod-01 | B6: poweredOn | C6: green | D6: esxi-prod-02.lab | E6: DC-Paris | F6: PROD-Cluster-01 | G6: 200 | H6: 150 | I6: 28% | J6: 245760 | K6: 131072 | L6: 4
A7: vm-app-prod-02 | B7: poweredOn | C7: yellow | D7: esxi-prod-02.lab | E7: DC-Paris | F7: PROD-Cluster-01 | G7: 200 | H7: 160 | I7: 31% | J7: 245760 | K7: 131072 | L7: 4
A8: vm-api-prod-01 | B8: poweredOn | C8: green | D8: esxi-prod-03.lab | E8: DC-Paris | F8: PROD-Cluster-01 | G8: 80 | H8: 55 | I8: 10% | J8: 180000 | K8: 65536 | L8: 2
A9: vm-db-prod-02 | B9: poweredOn | C9: green | D9: esxi-prod-04.lab | E9: DC-Paris | F9: PROD-Cluster-02 | G9: 800 | H9: 650 | I9: 55% | J9: 262144 | K9: 196608 | L9: 8
A10: vm-erp-prod-01 | B10: poweredOn | C10: green | D10: esxi-prod-04.lab | E10: DC-Paris | F10: PROD-Cluster-02 | G10: 600 | H10: 520 | I10: 45% | J10: 262144 | K10: 180000 | L10: 16
A11: vm-backup-prod-01 | B11: poweredOn | C11: green | D11: esxi-prod-05.lab | E11: DC-Paris | F11: PROD-Cluster-02 | G11: 2000 | H11: 1800 | I11: 8% | J11: 262144 | K11: 32768 | L11: 4
A12: vm-dev-01 | B12: poweredOn | C12: green | D12: esxi-dev-01.lab | E12: DC-Nantes | F12: DEV-Cluster-01 | G12: 80 | H12: 40 | I12: 5% | J12: 45000 | K12: 16384 | L12: 2
A13: vm-dev-02 | B13: poweredOff | C13: green | D13: esxi-dev-01.lab | E13: DC-Nantes | F13: DEV-Cluster-01 | G13: 120 | H13: 100 | I13: 0% | J13: 0 | K13: 0 | L13: 4
A14: vm-test-01 | B14: poweredOn | C14: yellow | D14: esxi-dev-02.lab | E14: DC-Nantes | F14: DEV-Cluster-01 | G14: 60 | H14: 30 | I14: 3% | J14: 35000 | K14: 10000 | L14: 2
A15: vm-test-02 | B15: poweredOff | C15: red | D15: esxi-dev-02.lab | E15: DC-Nantes | F15: DEV-Cluster-01 | G15: 60 | H15: 25 | I15: 0% | J15: 0 | K15: 0 | L15: 2

Sheet 📊 Capacity_Hosts
A1: 📊 ANALYSE CAPACITÉ – COMPUTE (CPU & RAM)
A2: Alimenté automatiquement par 🖥️ RAW_Hosts | Ne pas modifier les cellules noires
A5: 📊 INDICATEURS GLOBAUX COMPUTE
A6: Hosts Connectés | D6: Total vCPUs | G6: CPU Libre moy. | J6: RAM Totale | M6: CPU Consommé moy. | P6: Cœurs libres tot.
A7: =COUNTIF('🖥️ RAW_Hosts'!B4:B200,"connected") | D7: =SUMIF('🖥️ RAW_Hosts'!B4:B200,"connected",'🖥️ RAW_Hosts'!H4:H200) | G7: =IFERROR(AVERAGEIF('🖥️ RAW_Hosts'!B4:B200,"connected",'🖥️ RAW_Hosts'!I4:I200),0) | J7: =IFERROR(ROUND(SUMIF('🖥️ RAW_Hosts'!B4:B200,"connected",'🖥️ RAW_Hosts'!G4:G200)/1024,0),0) | M7: =IFERROR(AVERAGEIF('🖥️ RAW_Hosts'!B4:B200,"connected",'🖥️ RAW_Hosts'!F4:F200),0) | P7: =SUMIF('🖥️ RAW_Hosts'!B4:B200,"connected",'🖥️ RAW_Hosts'!J4:J200)
A8: hosts actifs | D8: CPUs logiques | G8: CPU free % moy. | J8: GB total | M8: CPU used % moy. | P8: cores disponibles
A10: 📋 DÉTAIL PAR HOST
A11: Name | B11: State | C11: Status | D11: ClusterDC | E11: Cluster | F11: Consumed CPU % | G11: CPU Free % | H11: CPU Free Cores | I11: Total CPUs | J11: CPU Statut | K11: Mem Total (MB) | L11: Mem Total (GB) | M11: RAM Utilisée | N11: RAM Statut | O11: NICs | P11: Alertes
A12: ='🖥️ RAW_Hosts'!A4 | B12: ='🖥️ RAW_Hosts'!B4 | C12: ='🖥️ RAW_Hosts'!C4 | D12: ='🖥️ RAW_Hosts'!D4 | E12: ='🖥️ RAW_Hosts'!E4 | F12: ='🖥️ RAW_Hosts'!F4 | G12: ='🖥️ RAW_Hosts'!I4 | H12: ='🖥️ RAW_Hosts'!J4 | I12: ='🖥️ RAW_Hosts'!H4 | J12: =IF(ISNUMBER(F12),IF(F12<0.7,"✅ OK",IF(F12<0.85,"⚠️ Warning","🔴 Critique")),IF(VALUE(SUBSTITUTE(F12,"%",""))/100<0.7,"✅ OK",IF(VALUE(SUBSTITUTE(F12,"%",""))/100<0.85,"⚠️ Warning","🔴 Critique"))) | K12: ='🖥️ RAW_Hosts'!G4 | L12: =IFERROR(K12/1024,0) | M12: ='🖥️ RAW_Hosts'!L4 | N12: =IF(ISNUMBER(M12),IF(M12/K12<0.75,"✅ OK",IF(M12/K12<0.90,"⚠️ Warning","🔴 Critique")),"—") | O12: ='🖥️ RAW_Hosts'!K4 | P12: =IF(B12<>"connected","⚠️ Host déconnecté",IF(C12="red","🔴 Statut critique","✅ "))
A13: ='🖥️ RAW_Hosts'!A5 | B13: ='🖥️ RAW_Hosts'!B5 | C13: ='🖥️ RAW_Hosts'!C5 | D13: ='🖥️ RAW_Hosts'!D5 | E13: ='🖥️ RAW_Hosts'!E5 | F13: ='🖥️ RAW_Hosts'!F5 | G13: ='🖥️ RAW_Hosts'!I5 | H13: ='🖥️ RAW_Hosts'!J5 | I13: ='🖥️ RAW_Hosts'!H5 | J13: =IF(ISNUMBER(F13),IF(F13<0.7,"✅ OK",IF(F13<0.85,"⚠️ Warning","🔴 Critique")),IF(VALUE(SUBSTITUTE(F13,"%",""))/100<0.7,"✅ OK",IF(VALUE(SUBSTITUTE(F13,"%",""))/100<0.85,"⚠️ Warning","🔴 Critique"))) | K13: ='🖥️ RAW_Hosts'!G5 | L13: =IFERROR(K13/1024,0) | M13: ='🖥️ RAW_Hosts'!L5 | N13: =IF(ISNUMBER(M13),IF(M13/K13<0.75,"✅ OK",IF(M13/K13<0.90,"⚠️ Warning","🔴 Critique")),"—") | O13: ='🖥️ RAW_Hosts'!K5 | P13: =IF(B13<>"connected","⚠️ Host déconnecté",IF(C13="red","🔴 Statut critique","✅ "))
A14: ='🖥️ RAW_Hosts'!A6 | B14: ='🖥️ RAW_Hosts'!B6 | C14: ='🖥️ RAW_Hosts'!C6 | D14: ='🖥️ RAW_Hosts'!D6 | E14: ='🖥️ RAW_Hosts'!E6 | F14: ='🖥️ RAW_Hosts'!F6 | G14: ='🖥️ RAW_Hosts'!I6 | H14: ='🖥️ RAW_Hosts'!J6 | I14: ='🖥️ RAW_Hosts'!H6 | J14: =IF(ISNUMBER(F14),IF(F14<0.7,"✅ OK",IF(F14<0.85,"⚠️ Warning","🔴 Critique")),IF(VALUE(SUBSTITUTE(F14,"%",""))/100<0.7,"✅ OK",IF(VALUE(SUBSTITUTE(F14,"%",""))/100<0.85,"⚠️ Warning","🔴 Critique"))) | K14: ='🖥️ RAW_Hosts'!G6 | L14: =IFERROR(K14/1024,0) | M14: ='🖥️ RAW_Hosts'!L6 | N14: =IF(ISNUMBER(M14),IF(M14/K14<0.75,"✅ OK",IF(M14/K14<0.90,"⚠️ Warning","🔴 Critique")),"—") | O14: ='🖥️ RAW_Hosts'!K6 | P14: =IF(B14<>"connected","⚠️ Host déconnecté",IF(C14="red","🔴 Statut critique","✅ "))
A15: ='🖥️ RAW_Hosts'!A7 | B15: ='🖥️ RAW_Hosts'!B7 | C15: ='🖥️ RAW_Hosts'!C7 | D15: ='🖥️ RAW_Hosts'!D7 | E15: ='🖥️ RAW_Hosts'!E7 | F15: ='🖥️ RAW_Hosts'!F7 | G15: ='🖥️ RAW_Hosts'!I7 | H15: ='🖥️ RAW_Hosts'!J7 | I15: ='🖥️ RAW_Hosts'!H7 | J15: =IF(ISNUMBER(F15),IF(F15<0.7,"✅ OK",IF(F15<0.85,"⚠️ Warning","🔴 Critique")),IF(VALUE(SUBSTITUTE(F15,"%",""))/100<0.7,"✅ OK",IF(VALUE(SUBSTITUTE(F15,"%",""))/100<0.85,"⚠️ Warning","🔴 Critique"))) | K15: ='🖥️ RAW_Hosts'!G7 | L15: =IFERROR(K15/1024,0) | M15: ='🖥️ RAW_Hosts'!L7 | N15: =IF(ISNUMBER(M15),IF(M15/K15<0.75,"✅ OK",IF(M15/K15<0.90,"⚠️ Warning","🔴 Critique")),"—") | O15: ='🖥️ RAW_Hosts'!K7 | P15: =IF(B15<>"connected","⚠️ Host déconnecté",IF(C15="red","🔴 Statut critique","✅ "))
A16: ='🖥️ RAW_Hosts'!A8 | B16: ='🖥️ RAW_Hosts'!B8 | C16: ='🖥️ RAW_Hosts'!C8 | D16: ='🖥️ RAW_Hosts'!D8 | E16: ='🖥️ RAW_Hosts'!E8 | F16: ='🖥️ RAW_Hosts'!F8 | G16: ='🖥️ RAW_Hosts'!I8 | H16: ='🖥️ RAW_Hosts'!J8 | I16: ='🖥️ RAW_Hosts'!H8 | J16: =IF(ISNUMBER(F16),IF(F16<0.7,"✅ OK",IF(F16<0.85,"⚠️ Warning","🔴 Critique")),IF(VALUE(SUBSTITUTE(F16,"%",""))/100<0.7,"✅ OK",IF(VALUE(SUBSTITUTE(F16,"%",""))/100<0.85,"⚠️ Warning","🔴 Critique"))) | K16: ='🖥️ RAW_Hosts'!G8 | L16: =IFERROR(K16/1024,0) | M16: ='🖥️ RAW_Hosts'!L8 | N16: =IF(ISNUMBER(M16),IF(M16/K16<0.75,"✅ OK",IF(M16/K16<0.90,"⚠️ Warning","🔴 Critique")),"—") | O16: ='🖥️ RAW_Hosts'!K8 | P16: =IF(B16<>"connected","⚠️ Host déconnecté",IF(C16="red","🔴 Statut critique","✅ "))
A17: ='🖥️ RAW_Hosts'!A9 | B17: ='🖥️ RAW_Hosts'!B9 | C17: ='🖥️ RAW_Hosts'!C9 | D17: ='🖥️ RAW_Hosts'!D9 | E17: ='🖥️ RAW_Hosts'!E9 | F17: ='🖥️ RAW_Hosts'!F9 | G17: ='🖥️ RAW_Hosts'!I9 | H17: ='🖥️ RAW_Hosts'!J9 | I17: ='🖥️ RAW_Hosts'!H9 | J17: =IF(ISNUMBER(F17),IF(F17<0.7,"✅ OK",IF(F17<0.85,"⚠️ Warning","🔴 Critique")),IF(VALUE(SUBSTITUTE(F17,"%",""))/100<0.7,"✅ OK",IF(VALUE(SUBSTITUTE(F17,"%",""))/100<0.85,"⚠️ Warning","🔴 Critique"))) | K17: ='🖥️ RAW_Hosts'!G9 | L17: =IFERROR(K17/1024,0) | M17: ='🖥️ RAW_Hosts'!L9 | N17: =IF(ISNUMBER(M17),IF(M17/K17<0.75,"✅ OK",IF(M17/K17<0.90,"⚠️ Warning","🔴 Critique")),"—") | O17: ='🖥️ RAW_Hosts'!K9 | P17: =IF(B17<>"connected","⚠️ Host déconnecté",IF(C17="red","🔴 Statut critique","✅ "))
A18: ='🖥️ RAW_Hosts'!A10 | B18: ='🖥️ RAW_Hosts'!B10 | C18: ='🖥️ RAW_Hosts'!C10 | D18: ='🖥️ RAW_Hosts'!D10 | E18: ='🖥️ RAW_Hosts'!E10 | F18: ='🖥️ RAW_Hosts'!F10 | G18: ='🖥️ RAW_Hosts'!I10 | H18: ='🖥️ RAW_Hosts'!J10 | I18: ='🖥️ RAW_Hosts'!H10 | J18: =IF(ISNUMBER(F18),IF(F18<0.7,"✅ OK",IF(F18<0.85,"⚠️ Warning","🔴 Critique")),IF(VALUE(SUBSTITUTE(F18,"%",""))/100<0.7,"✅ OK",IF(VALUE(SUBSTITUTE(F18,"%",""))/100<0.85,"⚠️ Warning","🔴 Critique"))) | K18: ='🖥️ RAW_Hosts'!G10 | L18: =IFERROR(K18/1024,0) | M18: ='🖥️ RAW_Hosts'!L10 | N18: =IF(ISNUMBER(M18),IF(M18/K18<0.75,"✅ OK",IF(M18/K18<0.90,"⚠️ Warning","🔴 Critique")),"—") | O18: ='🖥️ RAW_Hosts'!K10 | P18: =IF(B18<>"connected","⚠️ Host déconnecté",IF(C18="red","🔴 Statut critique","✅ "))
A19: TOTAUX / MOYENNES | H19: =SUM(H12:H18) | I19: =SUM(I12:I18) | K19: =SUM(K12:K18) | L19: =ROUND(SUM(K12:K18)/1024,1) | O19: =SUM(O12:O18)
A21: 📈 GRAPHIQUES CPU & RAM PAR HOST

Sheet 💽 Capacity_Storage
A1: 💽 ANALYSE CAPACITÉ – STOCKAGE
A2: Alimenté automatiquement par 💾 RAW_Datastores | Ne pas modifier les cellules noires
A5: 📊 INDICATEURS GLOBAUX STOCKAGE
A6: Cap. Totale (TB) | D6: Cap. Totale (GB) | G6: Espace Libre (GB) | J6: Usage Global | M6: Datastores
A7: =IFERROR(ROUND(SUM('💾 RAW_Datastores'!F4:F200),1),0) | D7: =IFERROR(ROUND(SUM('💾 RAW_Datastores'!G4:G200),0),0) | G7: =IFERROR(ROUND(SUM('💾 RAW_Datastores'!H4:H200),0),0) | J7: =IFERROR(1-SUM('💾 RAW_Datastores'!H4:H200)/SUM('💾 RAW_Datastores'!G4:G200),0) | M7: =COUNTA('💾 RAW_Datastores'!A4:A200)-COUNTBLANK('💾 RAW_Datastores'!A4:A200)
A8: TB total | D8: GB total | G8: GB libres | J8: % utilisé | M8: nb datastores
A10: 📋 DÉTAIL PAR DATASTORE
A11: Name | B11: Cluster | C11: Status | D11: Type | E11: DS Cluster | F11: Capacity TB | G11: Capacity (GB) | H11: Free (GB) | I11: FreeSize | J11: Used (GB) | K11: Usage % | L11: Statut | M11: Alertes
A12: ='💾 RAW_Datastores'!A4 | B12: ='💾 RAW_Datastores'!B4 | C12: ='💾 RAW_Datastores'!C4 | D12: ='💾 RAW_Datastores'!D4 | E12: ='💾 RAW_Datastores'!E4 | F12: ='💾 RAW_Datastores'!F4 | G12: ='💾 RAW_Datastores'!G4 | H12: ='💾 RAW_Datastores'!H4 | I12: ='💾 RAW_Datastores'!I4 | J12: =IFERROR(G12-H12,0) | K12: =IFERROR(J12/G12,0) | L12: =IF(K12<0.7,"✅ OK",IF(K12<0.85,"⚠️ Warning","🔴 Critique")) | M12: =IF(C12="red","🔴 Statut rouge",IF(K12>0.90,"🔴 Espace critique",IF(K12>0.80,"⚠️ Surveiller","✅ Normal")))
A13: ='💾 RAW_Datastores'!A5 | B13: ='💾 RAW_Datastores'!B5 | C13: ='💾 RAW_Datastores'!C5 | D13: ='💾 RAW_Datastores'!D5 | E13: ='💾 RAW_Datastores'!E5 | F13: ='💾 RAW_Datastores'!F5 | G13: ='💾 RAW_Datastores'!G5 | H13: ='💾 RAW_Datastores'!H5 | I13: ='💾 RAW_Datastores'!I5 | J13: =IFERROR(G13-H13,0) | K13: =IFERROR(J13/G13,0) | L13: =IF(K13<0.7,"✅ OK",IF(K13<0.85,"⚠️ Warning","🔴 Critique")) | M13: =IF(C13="red","🔴 Statut rouge",IF(K13>0.90,"🔴 Espace critique",IF(K13>0.80,"⚠️ Surveiller","✅ Normal")))
A14: ='💾 RAW_Datastores'!A6 | B14: ='💾 RAW_Datastores'!B6 | C14: ='💾 RAW_Datastores'!C6 | D14: ='💾 RAW_Datastores'!D6 | E14: ='💾 RAW_Datastores'!E6 | F14: ='💾 RAW_Datastores'!F6 | G14: ='💾 RAW_Datastores'!G6 | H14: ='💾 RAW_Datastores'!H6 | I14: ='💾 RAW_Datastores'!I6 | J14: =IFERROR(G14-H14,0) | K14: =IFERROR(J14/G14,0) | L14: =IF(K14<0.7,"✅ OK",IF(K14<0.85,"⚠️ Warning","🔴 Critique")) | M14: =IF(C14="red","🔴 Statut rouge",IF(K14>0.90,"🔴 Espace critique",IF(K14>0.80,"⚠️ Surveiller","✅ Normal")))
A15: ='💾 RAW_Datastores'!A7 | B15: ='💾 RAW_Datastores'!B7 | C15: ='💾 RAW_Datastores'!C7 | D15: ='💾 RAW_Datastores'!D7 | E15: ='💾 RAW_Datastores'!E7 | F15: ='💾 RAW_Datastores'!F7 | G15: ='💾 RAW_Datastores'!G7 | H15: ='💾 RAW_Datastores'!H7 | I15: ='💾 RAW_Datastores'!I7 | J15: =IFERROR(G15-H15,0) | K15: =IFERROR(J15/G15,0) | L15: =IF(K15<0.7,"✅ OK",IF(K15<0.85,"⚠️ Warning","🔴 Critique")) | M15: =IF(C15="red","🔴 Statut rouge",IF(K15>0.90,"🔴 Espace critique",IF(K15>0.80,"⚠️ Surveiller","✅ Normal")))
A16: ='💾 RAW_Datastores'!A8 | B16: ='💾 RAW_Datastores'!B8 | C16: ='💾 RAW_Datastores'!C8 | D16: ='💾 RAW_Datastores'!D8 | E16: ='💾 RAW_Datastores'!E8 | F16: ='💾 RAW_Datastores'!F8 | G16: ='💾 RAW_Datastores'!G8 | H16: ='💾 RAW_Datastores'!H8 | I16: ='💾 RAW_Datastores'!I8 | J16: =IFERROR(G16-H16,0) | K16: =IFERROR(J16/G16,0) | L16: =IF(K16<0.7,"✅ OK",IF(K16<0.85,"⚠️ Warning","🔴 Critique")) | M16: =IF(C16="red","🔴 Statut rouge",IF(K16>0.90,"🔴 Espace critique",IF(K16>0.80,"⚠️ Surveiller","✅ Normal")))
A17: ='💾 RAW_Datastores'!A9 | B17: ='💾 RAW_Datastores'!B9 | C17: ='💾 RAW_Datastores'!C9 | D17: ='💾 RAW_Datastores'!D9 | E17: ='💾 RAW_Datastores'!E9 | F17: ='💾 RAW_Datastores'!F9 | G17: ='💾 RAW_Datastores'!G9 | H17: ='💾 RAW_Datastores'!H9 | I17: ='💾 RAW_Datastores'!I9 | J17: =IFERROR(G17-H17,0) | K17: =IFERROR(J17/G17,0) | L17: =IF(K17<0.7,"✅ OK",IF(K17<0.85,"⚠️ Warning","🔴 Critique")) | M17: =IF(C17="red","🔴 Statut rouge",IF(K17>0.90,"🔴 Espace critique",IF(K17>0.80,"⚠️ Surveiller","✅ Normal")))
A18: ='💾 RAW_Datastores'!A10 | B18: ='💾 RAW_Datastores'!B10 | C18: ='💾 RAW_Datastores'!C10 | D18: ='💾 RAW_Datastores'!D10 | E18: ='💾 RAW_Datastores'!E10 | F18: ='💾 RAW_Datastores'!F10 | G18: ='💾 RAW_Datastores'!G10 | H18: ='💾 RAW_Datastores'!H10 | I18: ='💾 RAW_Datastores'!I10 | J18: =IFERROR(G18-H18,0) | K18: =IFERROR(J18/G18,0) | L18: =IF(K18<0.7,"✅ OK",IF(K18<0.85,"⚠️ Warning","🔴 Critique")) | M18: =IF(C18="red","🔴 Statut rouge",IF(K18>0.90,"🔴 Espace critique",IF(K18>0.80,"⚠️ Surveiller","✅ Normal")))
A19: ='💾 RAW_Datastores'!A11 | B19: ='💾 RAW_Datastores'!B11 | C19: ='💾 RAW_Datastores'!C11 | D19: ='💾 RAW_Datastores'!D11 | E19: ='💾 RAW_Datastores'!E11 | F19: ='💾 RAW_Datastores'!F11 | G19: ='💾 RAW_Datastores'!G11 | H19: ='💾 RAW_Datastores'!H11 | I19: ='💾 RAW_Datastores'!I11 | J19: =IFERROR(G19-H19,0) | K19: =IFERROR(J19/G19,0) | L19: =IF(K19<0.7,"✅ OK",IF(K19<0.85,"⚠️ Warning","🔴 Critique")) | M19: =IF(C19="red","🔴 Statut rouge",IF(K19>0.90,"🔴 Espace critique",IF(K19>0.80,"⚠️ Surveiller","✅ Normal")))
A20: ='💾 RAW_Datastores'!A12 | B20: ='💾 RAW_Datastores'!B12 | C20: ='💾 RAW_Datastores'!C12 | D20: ='💾 RAW_Datastores'!D12 | E20: ='💾 RAW_Datastores'!E12 | F20: ='💾 RAW_Datastores'!F12 | G20: ='💾 RAW_Datastores'!G12 | H20: ='💾 RAW_Datastores'!H12 | I20: ='💾 RAW_Datastores'!I12 | J20: =IFERROR(G20-H20,0) | K20: =IFERROR(J20/G20,0) | L20: =IF(K20<0.7,"✅ OK",IF(K20<0.85,"⚠️ Warning","🔴 Critique")) | M20: =IF(C20="red","🔴 Statut rouge",IF(K20>0.90,"🔴 Espace critique",IF(K20>0.80,"⚠️ Surveiller","✅ Normal")))
A21: TOTAUX | F21: =SUM(F12:F20) | G21: =SUM(G12:G20) | H21: =SUM(H12:H20) | J21: =SUM(J12:J20) | K21: =IFERROR(SUM(J12:J20)/SUM(G12:G20),0)
A23: 📊 GRAPHIQUES STOCKAGE

Sheet 🔮 Projections
A1: 🔮 PROJECTIONS DE CAPACITÉ – 12 MOIS
A2: Modifier les cellules BLEUES pour ajuster les hypothèses de croissance
A5: ⚙️ HYPOTHÈSES DE CROISSANCE (modifiables)
A6: Croissance VMs / mois | B6: 0.05 | C6: ← Nb VMs +5% par mois
A7: Croissance CPU consommé / mois | B7: 0.04 | C7: ← CPU used% +4% par mois
A8: Croissance stockage / mois | B8: 0.06 | C8: ← Storage +6% par mois
A9: Croissance RAM consommée / mois | B9: 0.04 | C9: ← RAM +4% par mois
A10: Seuil alerte CPU (%) | B10: 0.8 | C10: ← Au-delà → Warning
A11: Seuil alerte RAM (%) | B11: 0.85 | C11: ← Au-delà → Warning
A12: Seuil alerte Stockage (%) | B12: 0.85 | C12: ← Au-delà → Warning
A13: Nombre de hosts planifiés | B13: 0 | C13: ← Hosts à ajouter (impact headroom)
A14: Capacité stockage planifiée(TB) | B14: 0 | C14: ← TB à ajouter aux datastores
A16: 📅 TABLEAU DE PROJECTION – M0 à M+12
A17: Indicateur | B17: M0 (Actuel) | C17: M+1 | D17: M+2 | E17: M+3 | F17: M+4 | G17: M+5 | H17: M+6 | I17: M+7 | J17: M+8 | K17: M+9 | L17: M+10 | M17: M+11 | N17: M+12
A18: ── MACHINES VIRTUELLES ──
A19: Nb VMs (total) | B19: =COUNTA('⚡ RAW_VMs'!A4:A500)-COUNTBLANK('⚡ RAW_VMs'!A4:A500) | C19: =B19*(1+B6) | D19: =C19*(1+B6) | E19: =D19*(1+B6) | F19: =E19*(1+B6) | G19: =F19*(1+B6) | H19: =G19*(1+B6) | I19: =H19*(1+B6) | J19: =I19*(1+B6) | K19: =J19*(1+B6) | L19: =K19*(1+B6) | M19: =L19*(1+B6) | N19: =M19*(1+B6)
A20: Nb VMs (poweredOn) | B20: =COUNTIF('⚡ RAW_VMs'!B4:B500,"poweredOn") | C20: =B20*(1+B6) | D20: =C20*(1+B6) | E20: =D20*(1+B6) | F20: =E20*(1+B6) | G20: =F20*(1+B6) | H20: =G20*(1+B6) | I20: =H20*(1+B6) | J20: =I20*(1+B6) | K20: =J20*(1+B6) | L20: =K20*(1+B6) | M20: =L20*(1+B6) | N20: =M20*(1+B6)
A21: ── CPU ──
A22: CPU consommé moy. (%) | B22: =IFERROR(AVERAGEIF('🖥️ RAW_Hosts'!B4:B200,"connected",'🖥️ RAW_Hosts'!F4:F200),0) | C22: =B22*(1+B7) | D22: =C22*(1+B7) | E22: =D22*(1+B7) | F22: =E22*(1+B7) | G22: =F22*(1+B7) | H22: =G22*(1+B7) | I22: =H22*(1+B7) | J22: =I22*(1+B7) | K22: =J22*(1+B7) | L22: =K22*(1+B7) | M22: =L22*(1+B7) | N22: =M22*(1+B7)
A23: Cœurs CPU libres (total) | B23: =SUMIF('🖥️ RAW_Hosts'!B4:B200,"connected",'🖥️ RAW_Hosts'!J4:J200) | C23: =B23 | D23: =C23 | E23: =D23 | F23: =E23 | G23: =F23 | H23: =G23 | I23: =H23 | J23: =I23 | ... N23: =M23
A24: Statut CPU | B24: =IF(B22="","",IF(ISNUMBER(B22),IF(B22<B10,"✅ OK",IF(B22<0.95,"⚠️ Warning","🔴 Critique")),"—")) | C24: =IF(C22="","",IF(ISNUMBER(C22),IF(C22<B10,"✅ OK",IF(C22<0.95,"⚠️ Warning","🔴 Critique")),"—")) | D24: =IF(D22="","",IF(ISNUMBER(D22),IF(D22<B10,"✅ OK",IF(D22<0.95,"⚠️ Warning","🔴 Critique")),"—")) | E24: =IF(E22="","",IF(ISNUMBER(E22),IF(E22<B10,"✅ OK",IF(E22<0.95,"⚠️ Warning","🔴 Critique")),"—")) | F24: =IF(F22="","",IF(ISNUMBER(F22),IF(F22<B10,"✅ OK",IF(F22<0.95,"⚠️ Warning","🔴 Critique")),"—")) | G24: =IF(G22="","",IF(ISNUMBER(G22),IF(G22<B10,"✅ OK",IF(G22<0.95,"⚠️ Warning","🔴 Critique")),"—")) | H24: =IF(H22="","",IF(ISNUMBER(H22),IF(H22<B10,"✅ OK",IF(H22<0.95,"⚠️ Warning","🔴 Critique")),"—")) | I24: =IF(I22="","",IF(ISNUMBER(I22),IF(I22<B10,"✅ OK",IF(I22<0.95,"⚠️ Warning","🔴 Critique")),"—")) | J24: =IF(J22="","",IF(ISNUMBER(J22),IF(J22<B10,"✅ OK",IF(J22<0.95,"⚠️ Warning","🔴 Critique")),"—")) | K24: =IF(K22="","",IF(ISNUMBER(K22),IF(K22<B10,"✅ OK",IF(K22<0.95,"⚠️ Warning","🔴 Critique")),"—")) | L24: =IF(L22="","",IF(ISNUMBER(L22),IF(L22<B10,"✅ OK",IF(L22<0.95,"⚠️ Warning","🔴 Critique")),"—")) | M24: =IF(M22="","",IF(ISNUMBER(M22),IF(M22<B10,"✅ OK",IF(M22<0.95,"⚠️ Warning","🔴 Critique")),"—")) | N24: =IF(N22="","",IF(ISNUMBER(N22),IF(N22<B10,"✅ OK",IF(N22<0.95,"⚠️ Warning","🔴 Critique")),"—"))
A25: ── MÉMOIRE ──
A26: RAM consommée moy. (MB) | B26: =IFERROR(AVERAGEIF('🖥️ RAW_Hosts'!B4:B200,"connected",'🖥️ RAW_Hosts'!L4:L200),0) | C26: =B26*(1+B9) | D26: =C26*(1+B9) | E26: =D26*(1+B9) | F26: =E26*(1+B9) | G26: =F26*(1+B9) | H26: =G26*(1+B9) | I26: =H26*(1+B9) | J26: =I26*(1+B9) | K26: =J26*(1+B9) | L26: =K26*(1+B9) | M26: =L26*(1+B9) | N26: =M26*(1+B9)
A27: RAM totale (GB) | B27: =IFERROR(ROUND(SUMIF('🖥️ RAW_Hosts'!B4:B200,"connected",'🖥️ RAW_Hosts'!G4:G200)/1024,0),0) | C27: =B27 | D27: =C27 | E27: =D27 | F27: =E27 | G27: =F27 | H27: =G27 | I27: =H27 | J27: =I27 | ... N27: =M27
A28: RAM Usage % | B28: =IFERROR(B26/(B27*1024),0) | C28: =IFERROR(C26/(C27*1024),0) | D28: =IFERROR(D26/(D27*1024),0) | E28: =IFERROR(E26/(E27*1024),0) | F28: =IFERROR(F26/(F27*1024),0) | G28: =IFERROR(G26/(G27*1024),0) | H28: =IFERROR(H26/(H27*1024),0) | I28: =IFERROR(I26/(I27*1024),0) | ... N28: =IFERROR(N26/(N27*1024),0)
A29: Statut RAM | B29: =IF(B28<B11,"✅ OK",IF(B28<0.95,"⚠️ Warning","🔴 Critique")) | C29: =IF(C28<B11,"✅ OK",IF(C28<0.95,"⚠️ Warning","🔴 Critique")) | D29: =IF(D28<B11,"✅ OK",IF(D28<0.95,"⚠️ Warning","🔴 Critique")) | E29: =IF(E28<B11,"✅ OK",IF(E28<0.95,"⚠️ Warning","🔴 Critique")) | F29: =IF(F28<B11,"✅ OK",IF(F28<0.95,"⚠️ Warning","🔴 Critique")) | G29: =IF(G28<B11,"✅ OK",IF(G28<0.95,"⚠️ Warning","🔴 Critique")) | H29: =IF(H28<B11,"✅ OK",IF(H28<0.95,"⚠️ Warning","🔴 Critique")) | I29: =IF(I28<B11,"✅ OK",IF(I28<0.95,"⚠️ Warning","🔴 Critique")) | J29: =IF(J28<B11,"✅ OK",IF(J28<0.95,"⚠️ Warning","🔴 Critique")) | K29: =IF(K28<B11,"✅ OK",IF(K28<0.95,"⚠️ Warning","🔴 Critique")) | L29: =IF(L28<B11,"✅ OK",IF(L28<0.95,"⚠️ Warning","🔴 Critique")) | M29: =IF(M28<B11,"✅ OK",IF(M28<0.95,"⚠️ Warning","🔴 Critique")) | N29: =IF(N28<B11,"✅ OK",IF(N28<0.95,"⚠️ Warning","🔴 Critique"))
A30: ── STOCKAGE ──
A31: Stockage utilisé (GB) | B31: =IFERROR(SUM('💾 RAW_Datastores'!G4:G200)-SUM('💾 RAW_Datastores'!H4:H200),0) | C31: =B31*(1+B8) | D31: =C31*(1+B8) | E31: =D31*(1+B8) | F31: =E31*(1+B8) | G31: =F31*(1+B8) | H31: =G31*(1+B8) | I31: =H31*(1+B8) | J31: =I31*(1+B8) | K31: =J31*(1+B8) | L31: =K31*(1+B8) | M31: =L31*(1+B8) | N31: =M31*(1+B8)
A32: Stockage total (GB) | B32: =IFERROR(SUM('💾 RAW_Datastores'!G4:G200),0) | C32: =B32 | D32: =C32 | E32: =D32 | F32: =E32 | G32: =F32 | H32: =G32 | I32: =H32 | J32: =I32 | ... N32: =M32
A33: Stockage Usage % | B33: =IFERROR(B31/B32,0) | C33: =IFERROR(C31/C32,0) | D33: =IFERROR(D31/D32,0) | E33: =IFERROR(E31/E32,0) | F33: =IFERROR(F31/F32,0) | G33: =IFERROR(G31/G32,0) | H33: =IFERROR(H31/H32,0) | I33: =IFERROR(I31/I32,0) | ... N33: =IFERROR(N31/N32,0)
A34: Statut Stockage | B34: =IF(B33<B12,"✅ OK",IF(B33<0.95,"⚠️ Warning","🔴 Critique")) | C34: =IF(C33<B12,"✅ OK",IF(C33<0.95,"⚠️ Warning","🔴 Critique")) | D34: =IF(D33<B12,"✅ OK",IF(D33<0.95,"⚠️ Warning","🔴 Critique")) | E34: =IF(E33<B12,"✅ OK",IF(E33<0.95,"⚠️ Warning","🔴 Critique")) | F34: =IF(F33<B12,"✅ OK",IF(F33<0.95,"⚠️ Warning","🔴 Critique")) | G34: =IF(G33<B12,"✅ OK",IF(G33<0.95,"⚠️ Warning","🔴 Critique")) | H34: =IF(H33<B12,"✅ OK",IF(H33<0.95,"⚠️ Warning","🔴 Critique")) | I34: =IF(I33<B12,"✅ OK",IF(I33<0.95,"⚠️ Warning","🔴 Critique")) | J34: =IF(J33<B12,"✅ OK",IF(J33<0.95,"⚠️ Warning","🔴 Critique")) | K34: =IF(K33<B12,"✅ OK",IF(K33<0.95,"⚠️ Warning","🔴 Critique")) | L34: =IF(L33<B12,"✅ OK",IF(L33<0.95,"⚠️ Warning","🔴 Critique")) | M34: =IF(M33<B12,"✅ OK",IF(M33<0.95,"⚠️ Warning","🔴 Critique")) | N34: =IF(N33<B12,"✅ OK",IF(N33<0.95,"⚠️ Warning","🔴 Critique"))
A37: 📈 GRAPHIQUES DE PROJECTION

Sheet 📈 Dashboard
B2: 📈 VMWARE CAPACITY PLANNING — DASHBOARD
B4: Généré le 23 March 2026 | vCenter 8.x
B6: 🖥️ COMPUTE
B7: Hosts connectés | F7: Total CPUs | J7: CPU Consommé | N7: CPU Free cores | R7: RAM Totale
B8: =COUNTIF('🖥️ RAW_Hosts'!B4:B200,"connected") | F8: =SUMIF('🖥️ RAW_Hosts'!B4:B200,"connected",'🖥️ RAW_Hosts'!H4:H200) | J8: =IFERROR(AVERAGEIF('🖥️ RAW_Hosts'!B4:B200,"connected",'🖥️ RAW_Hosts'!F4:F200),0) | N8: =SUMIF('🖥️ RAW_Hosts'!B4:B200,"connected",'🖥️ RAW_Hosts'!J4:J200) | R8: =IFERROR(ROUND(SUMIF('🖥️ RAW_Hosts'!B4:B200,"connected",'🖥️ RAW_Hosts'!G4:G200)/1024,0),0)
B9: hôtes actifs | F9: CPUs logiques | J9: moy. % used CPU | N9: cœurs disponibles | R9: GB cluster total
B11: 💽 STOCKAGE & VMs
B12: Total VMs | F12: VMs actives | J12: VMs éteintes | N12: Cap. Stockage | R12: Usage Stockage
B13: =COUNTA('⚡ RAW_VMs'!A4:A500)-COUNTBLANK('⚡ RAW_VMs'!A4:A500) | F13: =COUNTIF('⚡ RAW_VMs'!B4:B500,"poweredOn") | J13: =COUNTIF('⚡ RAW_VMs'!B4:B500,"poweredOff") | N13: =IFERROR(ROUND(SUM('💾 RAW_Datastores'!F4:F200),1),0) | R13: =IFERROR(1-SUM('💾 RAW_Datastores'!H4:H200)/SUM('💾 RAW_Datastores'!G4:G200),0)
B14: VMs inventaire | F14: poweredOn | J14: poweredOff | N14: TB total | R14: % utilisé global
B16: 🚨 ALERTES INFRASTRUCTURE
B17: Hosts État rouge | G17: =COUNTIF('🖥️ RAW_Hosts'!C4:C200,"red")
B18: Hosts Warning | G18: =COUNTIF('🖥️ RAW_Hosts'!C4:C200,"yellow")
B19: Datastores État rouge | G19: =COUNTIF('💾 RAW_Datastores'!C4:C200,"red")
B20: VMs Status rouge | G20: =COUNTIF('⚡ RAW_VMs'!C4:C500,"red")
B21: VMs Status yellow | G21: =COUNTIF('⚡ RAW_VMs'!C4:C500,"yellow")
B22: DS > 85% utilisé | G22: =COUNTIF('💽 Capacity_Storage'!K12:K20,">0.85")
B24: 📊 VISUALISATIONS
B45: State | C45: Nb VMs
B46: poweredOn | C46: =COUNTIF('⚡ RAW_VMs'!B4:B500,"poweredOn")
B47: poweredOff | C47: =COUNTIF('⚡ RAW_VMs'!B4:B500,"poweredOff")
