Workbook

Sheet 📋 Instructions
A1: 📋 VMware vCenter 8 – Capacity Planning
A2: v3.0 | 23/03/2026 | Tableaux dynamiques illimités
B4: 🗂️ STRUCTURE DU CLASSEUR
B5: Onglet | C5: Description | D5: Source | E5: Remarque
B6: 📋 Instructions | C6: Ce guide | D6: —
B7: 🖥️ RAW_Hosts | C7: Données brutes Hosts ESXi | D7: vCenter → Hosts → Export (coller en A4)
B8: 💾 RAW_Datastores | C8: Données brutes Datastores | D8: vCenter → Storage → Export (coller en A4)
B9: ⚡ RAW_VMs | C9: Données brutes VMs | D9: vCenter → VMs → Export (coller en A4)
B10: 📊 Capacity_Hosts | C10: Analyse CPU/RAM par host | D10: ← RAW_Hosts
B11: 💽 Capacity_Storage | C11: Analyse stockage | D11: ← RAW_Datastores
B12: 🔮 Projections | C12: Projections 12 mois | D12: ← Tous les RAW
B13: 📈 Dashboard | C13: KPIs + graphiques globaux | D13: ← Vue consolidée
B15: 📌 COMMENT IMPORTER VOS DONNÉES
B16: 1 | C16: Exporter depuis vCenter | D16: vCenter 8 → Menu Hôtes/Datastores/VMs → sélectionner toutes les colonnes → Exporter en CSV ou copier-coller
B17: 2 | C17: Ouvrir le bon onglet RAW | D17: Aller sur 🖥️ RAW_Hosts, 💾 RAW_Datastores ou ⚡ RAW_VMs selon le type de données
B18: 3 | C18: Supprimer les exemples | D18: Sélectionner les lignes 4 à la fin du tableau → Suppr (ne pas toucher la ligne 3 = en-têtes)
B19: 4 | C19: Coller vos données | D19: Coller à partir de la cellule A4. Le tableau Excel s'étend automatiquement — aucune limite de lignes.
B20: 5 | C20: Vérifier les colonnes | D20: S'assurer que les colonnes correspondent aux en-têtes de la ligne 3 (voir tableau ci-dessous)
B21: 6 | C21: Consulter le Dashboard | D21: Toutes les analyses se recalculent automatiquement. Aller sur 📈 Dashboard.
B23: 📥 COLONNES PAR ONGLET RAW (ligne 3 = en-têtes)
B24: 🖥️ RAW_Hosts
B25: Col | C25: Nom de colonne | D25: Description | E25: —
B26: A | C26: Name | D26: Nom du host ESXi
B27: B | C27: State | D27: connected / disconnected / maintenance
B28: C | C28: Status | D28: green / yellow / red
B29: D | C29: ClusterDatacenter | D29: Datacenter du cluster
B30: E | C30: Cluster | D30: Nom du cluster vSphere
B31: F | C31: Consumed CPU % | D31: Pourcentage CPU consommé (ex: 45% ou 0.45)
B32: G | C32: Memory Size (MB) | D32: RAM totale du host en MB
B33: H | C33: CPUs | D33: Nombre total de CPUs logiques
B34: I | C34: CPU Free % | D34: Pourcentage CPU libre
B35: J | C35: CPU free cores | D35: Nombre de cœurs libres
B36: K | C36: NICs | D36: Nombre de cartes réseau
B37: L | C37: RAM | D37: RAM consommée (MB)
B39: 💾 RAW_Datastores
B40: Col | C40: Nom de colonne | D40: Description | E40: —
B41: A | C41: Name | D41: Nom du datastore
B42: B | C42: Cluster | D42: Cluster vSphere associé
B43: C | C43: Status | D43: green / yellow / red
B44: D | C44: Type | D44: VMFS / NFS / vSAN / vVol
...

Sheet 🖥️ RAW_Hosts
A1: 🖥️ HOSTS ESXi – Données brutes vCenter 8
A2: ⚠️ Coller vos données à partir de A4 | Ligne 3 = en-têtes (ne pas modifier) | Tableau extensible sans limite
A3: Name | B3: State | C3: Status | D3: ClusterDatacenter | E3: Cluster | F3: Consumed CPU % | G3: Memory Size (MB) | H3: CPUs | I3: CPU Free % | J3: CPU free cores | K3: NICs | L3: RAM
A4: esxi-prod-01.lab | B4: connected | C4: green | D4: DC-Paris | E4: PROD-Cluster-01 | F4: 23% | G4: 393216 | H4: 40 | I4: 77% | J4: 31 | K4: 4 | L4: 91136
A5: esxi-prod-02.lab | B5: connected | C5: green | D5: DC-Paris | E5: PROD-Cluster-01 | F5: 55% | G5: 393216 | H5: 40 | I5: 45% | J5: 18 | K5: 4 | L5: 245760
A6: esxi-prod-03.lab | B6: connected | C6: green | D6: DC-Paris | E6: PROD-Cluster-01 | F6: 39% | G6: 393216 | H6: 40 | I6: 61% | J6: 24 | K6: 4 | L6: 180000
A7: esxi-prod-04.lab | B7: connected | C7: green | D7: DC-Paris | E7: PROD-Cluster-02 | F7: 68% | G7: 262144 | H7: 32 | I7: 32% | J7: 10 | K7: 4 | L7: 220000
A8: esxi-prod-05.lab | B8: connected | C8: yellow | D8: DC-Paris | E8: PROD-Cluster-02 | F8: 81% | G8: 262144 | H8: 32 | I8: 19% | J8: 6 | K8: 4 | L8: 240000
A9: esxi-prod-06.lab | B9: connected | C9: green | D9: DC-Paris | E9: PROD-Cluster-02 | F9: 74% | G9: 262144 | H9: 32 | I9: 26% | J9: 8 | K9: 4 | L9: 210000
A10: esxi-dev-01.lab | B10: connected | C10: green | D10: DC-Nantes | E10: DEV-Cluster-01 | F10: 18% | G10: 196608 | H10: 24 | I10: 82% | J10: 20 | K10: 2 | L10: 45000
A11: esxi-dev-02.lab | B11: connected | C11: green | D11: DC-Nantes | E11: DEV-Cluster-01 | F11: 12% | G11: 196608 | H11: 24 | I11: 88% | J11: 21 | K11: 2 | L11: 35000
A12: esxi-dev-03.lab | B12: connected | C12: green | D12: DC-Nantes | E12: DEV-Cluster-01 | F12: 9% | G12: 196608 | H12: 24 | I12: 91% | J12: 22 | K12: 2 | L12: 28000
A13: esxi-dr-01.lab | B13: connected | C13: green | D13: DC-Lyon | E13: DR-Cluster-01 | F13: 5% | G13: 524288 | H13: 48 | I13: 95% | J13: 46 | K13: 4 | L13: 30000
A15: 💡 Pour ajouter des lignes : cliquer sur la dernière cellule du tableau et appuyer sur Tab — le tableau s'étend automatiquement.

Sheet 💾 RAW_Datastores
A1: 💾 DATASTORES – Données brutes vCenter 8
A2: ⚠️ Coller vos données à partir de A4 | Ligne 3 = en-têtes (ne pas modifier) | Tableau extensible sans limite
A3: Name | B3: Cluster | C3: Status | D3: Type | E3: Datastore cluster | F3: Capacity TB | G3: Capacity | H3: Free | I3: FreeSize
A4: PROD-DS-SAN-01 | B4: PROD-Cluster-01 | C4: green | D4: VMFS | E4: PROD-DsCluster | F4: 10 | G4: 10240 | H4: 2800 | I4: 2.7
A5: PROD-DS-SAN-02 | B5: PROD-Cluster-01 | C5: yellow | D5: VMFS | E5: PROD-DsCluster | F5: 10 | G5: 10240 | H5: 1100 | I5: 1.1
A6: PROD-DS-NFS-01 | B6: PROD-Cluster-01 | C6: green | D6: NFS | F6: 5 | G6: 5120 | H6: 1800 | I6: 1.8
A7: PROD-DS-SAN-03 | B7: PROD-Cluster-02 | C7: green | D7: VMFS | E7: PROD-DsCluster-2 | F7: 8 | G7: 8192 | H7: 3500 | I7: 3.4
A8: PROD-DS-SAN-04 | B8: PROD-Cluster-02 | C8: red | D8: VMFS | E8: PROD-DsCluster-2 | F8: 8 | G8: 8192 | H8: 400 | I8: 0.4
A9: PROD-DS-VSAN-01 | B9: PROD-Cluster-02 | C9: green | D9: vSAN | F9: 15 | G9: 15360 | H9: 6000 | I9: 5.9
A10: DEV-DS-NFS-01 | B10: DEV-Cluster-01 | C10: green | D10: NFS | F10: 4 | G10: 4096 | H10: 2100 | I10: 2
A11: DEV-DS-SAN-01 | B11: DEV-Cluster-01 | C11: green | D11: VMFS | F11: 2 | G11: 2048 | H11: 800 | I11: 0.8
A12: ARCHIVE-DS-01 | B12: DEV-Cluster-01 | C12: green | D12: NFS | F12: 20 | G12: 20480 | H12: 8000 | I12: 7.8
A13: DR-DS-SAN-01 | B13: DR-Cluster-01 | C13: green | D13: VMFS | E13: DR-DsCluster | F13: 12 | G13: 12288 | H13: 9000 | I13: 8.8
A15: 💡 Pour ajouter des lignes : cliquer sur la dernière cellule du tableau et appuyer sur Tab.

Sheet ⚡ RAW_VMs
A1: ⚡ MACHINES VIRTUELLES – Données brutes vCenter 8
A2: ⚠️ Coller vos données à partir de A4 | Ligne 3 = en-têtes (ne pas modifier) | Tableau extensible — prévu pour 2000+ VMs
A3: Name | B3: State | C3: Status | D3: Host | E3: ClusterDatacenter | F3: Cluster | G3: Provisioned Space | H3: Used Space | I3: Host CPU | J3: Host Mem | K3: Active Memory | L3: CPUs
A4: vm-web-prod-01 | B4: poweredOn | C4: green | D4: esxi-prod-01.lab | E4: DC-Paris | F4: PROD-Cluster-01 | G4: 120 | H4: 85 | I4: 18% | J4: 91136 | K4: 65536 | L4: 4
A5: vm-db-prod-01 | B5: poweredOn | C5: green | D5: esxi-prod-01.lab | E5: DC-Paris | F5: PROD-Cluster-01 | G5: 500 | H5: 420 | I5: 62% | J5: 393216 | K5: 280000 | L5: 8
A6: vm-app-prod-01 | B6: poweredOn | C6: green | D6: esxi-prod-02.lab | E6: DC-Paris | F6: PROD-Cluster-01 | G6: 200 | H6: 150 | I6: 28% | J6: 245760 | K6: 131072 | L6: 4
A7: vm-app-prod-02 | B7: poweredOn | C7: yellow | D7: esxi-prod-02.lab | E7: DC-Paris | F7: PROD-Cluster-01 | G7: 200 | H7: 160 | I7: 31% | J7: 245760 | K7: 131072 | L7: 4
A8: vm-api-prod-01 | B8: poweredOn | C8: green | D8: esxi-prod-03.lab | E8: DC-Paris | F8: PROD-Cluster-01 | G8: 80 | H8: 55 | I8: 10% | J8: 180000 | K8: 65536 | L8: 2
A9: vm-db-prod-02 | B9: poweredOn | C9: green | D9: esxi-prod-04.lab | E9: DC-Paris | F9: PROD-Cluster-02 | G9: 800 | H9: 650 | I9: 55% | J9: 262144 | K9: 196608 | L9: 8
A10: vm-erp-prod-01 | B10: poweredOn | C10: green | D10: esxi-prod-04.lab | E10: DC-Paris | F10: PROD-Cluster-02 | G10: 600 | H10: 520 | I10: 45% | J10: 262144 | K10: 180000 | L10: 16
A11: vm-backup-prod-01 | B11: poweredOn | C11: green | D11: esxi-prod-05.lab | E11: DC-Paris | F11: PROD-Cluster-02 | G11: 2000 | H11: 1800 | I11: 8% | J11: 262144 | K11: 32768 | L11: 4
A12: vm-erp-prod-02 | B12: poweredOn | C12: green | D12: esxi-prod-05.lab | E12: DC-Paris | F12: PROD-Cluster-02 | G12: 400 | H12: 350 | I12: 38% | J12: 262144 | K12: 150000 | L12: 8
A13: vm-middleware-01 | B13: poweredOn | C13: green | D13: esxi-prod-06.lab | E13: DC-Paris | F13: PROD-Cluster-02 | G13: 180 | H13: 120 | I13: 22% | J13: 262144 | K13: 98304 | L13: 4
A14: vm-dev-01 | B14: poweredOn | C14: green | D14: esxi-dev-01.lab | E14: DC-Nantes | F14: DEV-Cluster-01 | G14: 80 | H14: 40 | I14: 5% | J14: 45000 | K14: 16384 | L14: 2
A15: vm-dev-02 | B15: poweredOff | C15: green | D15: esxi-dev-01.lab | E15: DC-Nantes | F15: DEV-Cluster-01 | G15: 120 | H15: 100 | I15: 0% | J15: 0 | K15: 0 | L15: 4
... A20: vm-dr-02 | B20: poweredOff | C20: green | D20: esxi-dr-01.lab | E20: DC-Lyon | F20: DR-Cluster-01 | G20: 300 | H20: 280 | I20: 0% | J20: 0 | K20: 0 | L20: 4
A22: 💡 Tableau prévu pour 2000+ VMs. Coller vos données à partir de A4 — le tableau s'agrandit automatiquement.

Sheet 📊 Capacity_Hosts
A1: 📊 ANALYSE CAPACITÉ – COMPUTE (CPU & RAM)
A2: Alimenté automatiquement par 🖥️ RAW_Hosts | Recalcul instantané
A4: 📊 INDICATEURS GLOBAUX
A5: Hosts Connectés | D5: Total CPUs | G5: CPU Consommé moy. | J5: Cœurs CPU libres | M5: RAM Totale | P5: Hosts Warning/Err
A6: =COUNTIF('🖥️ RAW_Hosts'!B4:B5000,"connected") | D6: =SUMIF('🖥️ RAW_Hosts'!B4:B5000,"connected",'🖥️ RAW_Hosts'!H4:H5000) | G6: =IFERROR(AVERAGEIF('🖥️ RAW_Hosts'!B4:B5000,"connected",'🖥️ RAW_Hosts'!F4:F5000),0) | J6: =SUMIF('🖥️ RAW_Hosts'!B4:B5000,"connected",'🖥️ RAW_Hosts'!J4:J5000) | M6: =IFERROR(ROUND(SUMIF('🖥️ RAW_Hosts'!B4:B5000,"connected",'🖥️ RAW_Hosts'!G4:G5000)/1024,0),0) | P6: =COUNTIF('🖥️ RAW_Hosts'!C4:C5000,"yellow")+COUNTIF('🖥️ RAW_Hosts'!C4:C5000,"red")
A7: actifs | D7: CPUs logiques | G7: moy. used % | J7: cores libres | M7: GB total | P7: ⚠️ à contrôler
A9: 📋 DÉTAIL PAR HOST (alimenté depuis 🖥️ RAW_Hosts)
A10: Name | B10: State | C10: Status | D10: ClusterDC | E10: Cluster | F10: Consumed CPU % | G10: CPU Free % | H10: CPU free cores | I10: Total CPUs | J10: Statut CPU | K10: Mem Total (MB) | L10: Mem Total (GB) | M10: RAM (MB) | N10: Statut RAM | O10: NICs | P10: Alerte
A11: ='🖥️ RAW_Hosts'!A4 | B11: ='🖥️ RAW_Hosts'!B4 | C11: ='🖥️ RAW_Hosts'!C4 | D11: ='🖥️ RAW_Hosts'!D4 | E11: ='🖥️ RAW_Hosts'!E4 | F11: ='🖥️ RAW_Hosts'!F4 | G11: ='🖥️ RAW_Hosts'!I4 | H11: ='🖥️ RAW_Hosts'!J4 | I11: ='🖥️ RAW_Hosts'!H4 | J11: =IF(ISNUMBER(F11),IF(F11<0.7,"✅ OK",IF(F11<0.85,"⚠️ Warning","🔴 Critique")),IF(VALUE(SUBSTITUTE(F11,"%",""))/100<0.7,"✅ OK",IF(VALUE(SUBSTITUTE(F11,"%",""))/100<0.85,"⚠️ Warning","🔴 Critique"))) | K11: ='🖥️ RAW_Hosts'!G4 | L11: =IFERROR(K11/1024,0) | M11: ='🖥️ RAW_Hosts'!L4 | N11: =IF(K11>0,IF(M11/K11<0.75,"✅ OK",IF(M11/K11<0.90,"⚠️ Warning","🔴 Critique")),"—") | O11: ='🖥️ RAW_Hosts'!K4 | P11: =IF(B11<>"connected","⚠️ Déconnecté",IF(C11="red","🔴 Statut critique",IF(C11="yellow","⚠️ Warning","✅ OK")))
A12: ='🖥️ RAW_Hosts'!A5 | B12: ='🖥️ RAW_Hosts'!B5 | C12: ='🖥️ RAW_Hosts'!C5 | D12: ='🖥️ RAW_Hosts'!D5 | E12: ='🖥️ RAW_Hosts'!E5 | F12: ='🖥️ RAW_Hosts'!F5 | G12: ='🖥️ RAW_Hosts'!I5 | H12: ='🖥️ RAW_Hosts'!J5 | I12: ='🖥️ RAW_Hosts'!H5 | J12: =IF(ISNUMBER(F12),IF(F12<0.7,"✅ OK",IF(F12<0.85,"⚠️ Warning","🔴 Critique")),IF(VALUE(SUBSTITUTE(F12,"%",""))/100<0.7,"✅ OK",IF(VALUE(SUBSTITUTE(F12,"%",""))/100<0.85,"⚠️ Warning","🔴 Critique"))) | K12: ='🖥️ RAW_Hosts'!G5 | L12: =IFERROR(K12/1024,0) | M12: ='🖥️ RAW_Hosts'!L5 | N12: =IF(K12>0,IF(M12/K12<0.75,"✅ OK",IF(M12/K12<0.90,"⚠️ Warning","🔴 Critique")),"—") | O12: ='🖥️ RAW_Hosts'!K5 | P12: =IF(B12<>"connected","⚠️ Déconnecté",IF(C12="red","🔴 Statut critique",IF(C12="yellow","⚠️ Warning","✅ OK")))
A13: ='🖥️ RAW_Hosts'!A6 | B13: ='🖥️ RAW_Hosts'!B6 | C13: ='🖥️ RAW_Hosts'!C6 | D13: ='🖥️ RAW_Hosts'!D6 | E13: ='🖥️ RAW_Hosts'!E6 | F13: ='🖥️ RAW_Hosts'!F6 | G13: ='🖥️ RAW_Hosts'!I6 | H13: ='🖥️ RAW_Hosts'!J6 | I13: ='🖥️ RAW_Hosts'!H6 | J13: =IF(ISNUMBER(F13),IF(F13<0.7,"✅ OK",IF(F13<0.85,"⚠️ Warning","🔴 Critique")),IF(VALUE(SUBSTITUTE(F13,"%",""))/100<0.7,"✅ OK",IF(VALUE(SUBSTITUTE(F13,"%",""))/100<0.85,"⚠️ Warning","🔴 Critique"))) | K13: ='🖥️ RAW_Hosts'!G6 | L13: =IFERROR(K13/1024,0) | M13: ='🖥️ RAW_Hosts'!L6 | N13: =IF(K13>0,IF(M13/K13<0.75,"✅ OK",IF(M13/K13<0.90,"⚠️ Warning","🔴 Critique")),"—") | O13: ='🖥️ RAW_Hosts'!K6 | P13: =IF(B13<>"connected","⚠️ Déconnecté",IF(C13="red","🔴 Statut critique",IF(C13="yellow","⚠️ Warning","✅ OK")))
A14: ='🖥️ RAW_Hosts'!A7 | B14: ='🖥️ RAW_Hosts'!B7 | C14: ='🖥️ RAW_Hosts'!C7 | D14: ='🖥️ RAW_Hosts'!D7 | E14: ='🖥️ RAW_Hosts'!E7 | F14: ='🖥️ RAW_Hosts'!F7 | G14: ='🖥️ RAW_Hosts'!I7 | H14: ='🖥️ RAW_Hosts'!J7 | I14: ='🖥️ RAW_Hosts'!H7 | J14: =IF(ISNUMBER(F14),IF(F14<0.7,"✅ OK",IF(F14<0.85,"⚠️ Warning","🔴 Critique")),IF(VALUE(SUBSTITUTE(F14,"%",""))/100<0.7,"✅ OK",IF(VALUE(SUBSTITUTE(F14,"%",""))/100<0.85,"⚠️ Warning","🔴 Critique"))) | K14: ='🖥️ RAW_Hosts'!G7 | L14: =IFERROR(K14/1024,0) | M14: ='🖥️ RAW_Hosts'!L7 | N14: =IF(K14>0,IF(M14/K14<0.75,"✅ OK",IF(M14/K14<0.90,"⚠️ Warning","🔴 Critique")),"—") | O14: ='🖥️ RAW_Hosts'!K7 | P14: =IF(B14<>"connected","⚠️ Déconnecté",IF(C14="red","🔴 Statut critique",IF(C14="yellow","⚠️ Warning","✅ OK")))
A15: ='🖥️ RAW_Hosts'!A8 | B15: ='🖥️ RAW_Hosts'!B8 | C15: ='🖥️ RAW_Hosts'!C8 | D15: ='🖥️ RAW_Hosts'!D8 | E15: ='🖥️ RAW_Hosts'!E8 | F15: ='🖥️ RAW_Hosts'!F8 | G15: ='🖥️ RAW_Hosts'!I8 | H15: ='🖥️ RAW_Hosts'!J8 | I15: ='🖥️ RAW_Hosts'!H8 | J15: =IF(ISNUMBER(F15),IF(F15<0.7,"✅ OK",IF(F15<0.85,"⚠️ Warning","🔴 Critique")),IF(VALUE(SUBSTITUTE(F15,"%",""))/100<0.7,"✅ OK",IF(VALUE(SUBSTITUTE(F15,"%",""))/100<0.85,"⚠️ Warning","🔴 Critique"))) | K15: ='🖥️ RAW_Hosts'!G8 | L15: =IFERROR(K15/1024,0) | M15: ='🖥️ RAW_Hosts'!L8 | N15: =IF(K15>0,IF(M15/K15<0.75,"✅ OK",IF(M15/K15<0.90,"⚠️ Warning","🔴 Critique")),"—") | O15: ='🖥️ RAW_Hosts'!K8 | P15: =IF(B15<>"connected","⚠️ Déconnecté",IF(C15="red","🔴 Statut critique",IF(C15="yellow","⚠️ Warning","✅ OK")))
A16: ='🖥️ RAW_Hosts'!A9 | B16: ='🖥️ RAW_Hosts'!B9 | C16: ='🖥️ RAW_Hosts'!C9 | D16: ='🖥️ RAW_Hosts'!D9 | E16: ='🖥️ RAW_Hosts'!E9 | F16: ='🖥️ RAW_Hosts'!F9 | G16: ='🖥️ RAW_Hosts'!I9 | H16: ='🖥️ RAW_Hosts'!J9 | I16: ='🖥️ RAW_Hosts'!H9 | J16: =IF(ISNUMBER(F16),IF(F16<0.7,"✅ OK",IF(F16<0.85,"⚠️ Warning","🔴 Critique")),IF(VALUE(SUBSTITUTE(F16,"%",""))/100<0.7,"✅ OK",IF(VALUE(SUBSTITUTE(F16,"%",""))/100<0.85,"⚠️ Warning","🔴 Critique"))) | K16: ='🖥️ RAW_Hosts'!G9 | L16: =IFERROR(K16/1024,0) | M16: ='🖥️ RAW_Hosts'!L9 | N16: =IF(K16>0,IF(M16/K16<0.75,"✅ OK",IF(M16/K16<0.90,"⚠️ Warning","🔴 Critique")),"—") | O16: ='🖥️ RAW_Hosts'!K9 | P16: =IF(B16<>"connected","⚠️ Déconnecté",IF(C16="red","🔴 Statut critique",IF(C16="yellow","⚠️ Warning","✅ OK")))
A17: ='🖥️ RAW_Hosts'!A10 | B17: ='🖥️ RAW_Hosts'!B10 | C17: ='🖥️ RAW_Hosts'!C10 | D17: ='🖥️ RAW_Hosts'!D10 | E17: ='🖥️ RAW_Hosts'!E10 | F17: ='🖥️ RAW_Hosts'!F10 | G17: ='🖥️ RAW_Hosts'!I10 | H17: ='🖥️ RAW_Hosts'!J10 | I17: ='🖥️ RAW_Hosts'!H10 | J17: =IF(ISNUMBER(F17),IF(F17<0.7,"✅ OK",IF(F17<0.85,"⚠️ Warning","🔴 Critique")),IF(VALUE(SUBSTITUTE(F17,"%",""))/100<0.7,"✅ OK",IF(VALUE(SUBSTITUTE(F17,"%",""))/100<0.85,"⚠️ Warning","🔴 Critique"))) | K17: ='🖥️ RAW_Hosts'!G10 | L17: =IFERROR(K17/1024,0) | M17: ='🖥️ RAW_Hosts'!L10 | N17: =IF(K17>0,IF(M17/K17<0.75,"✅ OK",IF(M17/K17<0.90,"⚠️ Warning","🔴 Critique")),"—") | O17: ='🖥️ RAW_Hosts'!K10 | P17: =IF(B17<>"connected","⚠️ Déconnecté",IF(C17="red","🔴 Statut critique",IF(C17="yellow","⚠️ Warning","✅ OK")))
A18: ='🖥️ RAW_Hosts'!A11 | B18: ='🖥️ RAW_Hosts'!B11 | C18: ='🖥️ RAW_Hosts'!C11 | D18: ='🖥️ RAW_Hosts'!D11 | E18: ='🖥️ RAW_Hosts'!E11 | F18: ='🖥️ RAW_Hosts'!F11 | G18: ='🖥️ RAW_Hosts'!I11 | H18: ='🖥️ RAW_Hosts'!J11 | I18: ='🖥️ RAW_Hosts'!H11 | J18: =IF(ISNUMBER(F18),IF(F18<0.7,"✅ OK",IF(F18<0.85,"⚠️ Warning","🔴 Critique")),IF(VALUE(SUBSTITUTE(F18,"%",""))/100<0.7,"✅ OK",IF(VALUE(SUBSTITUTE(F18,"%",""))/100<0.85,"⚠️ Warning","🔴 Critique"))) | K18: ='🖥️ RAW_Hosts'!G11 | L18: =IFERROR(K18/1024,0) | M18: ='🖥️ RAW_Hosts'!L11 | N18: =IF(K18>0,IF(M18/K18<0.75,"✅ OK",IF(M18/K18<0.90,"⚠️ Warning","🔴 Critique")),"—") | O18: ='🖥️ RAW_Hosts'!K11 | P18: =IF(B18<>"connected","⚠️ Déconnecté",IF(C18="red","🔴 Statut critique",IF(C18="yellow","⚠️ Warning","✅ OK")))
A19: ='🖥️ RAW_Hosts'!A12 | B19: ='🖥️ RAW_Hosts'!B12 | C19: ='🖥️ RAW_Hosts'!C12 | D19: ='🖥️ RAW_Hosts'!D12 | E19: ='🖥️ RAW_Hosts'!E12 | F19: ='🖥️ RAW_Hosts'!F12 | G19: ='🖥️ RAW_Hosts'!I12 | H19: ='🖥️ RAW_Hosts'!J12 | I19: ='🖥️ RAW_Hosts'!H12 | J19: =IF(ISNUMBER(F19),IF(F19<0.7,"✅ OK",IF(F19<0.85,"⚠️ Warning","🔴 Critique")),IF(VALUE(SUBSTITUTE(F19,"%",""))/100<0.7,"✅ OK",IF(VALUE(SUBSTITUTE(F19,"%",""))/100<0.85,"⚠️ Warning","🔴 Critique"))) | K19: ='🖥️ RAW_Hosts'!G12 | L19: =IFERROR(K19/1024,0) | M19: ='🖥️ RAW_Hosts'!L12 | N19: =IF(K19>0,IF(M19/K19<0.75,"✅ OK",IF(M19/K19<0.90,"⚠️ Warning","🔴 Critique")),"—") | O19: ='🖥️ RAW_Hosts'!K12 | P19: =IF(B19<>"connected","⚠️ Déconnecté",IF(C19="red","🔴 Statut critique",IF(C19="yellow","⚠️ Warning","✅ OK")))
A20: ='🖥️ RAW_Hosts'!A13 | B20: ='🖥️ RAW_Hosts'!B13 | C20: ='🖥️ RAW_Hosts'!C13 | D20: ='🖥️ RAW_Hosts'!D13 | E20: ='🖥️ RAW_Hosts'!E13 | F20: ='🖥️ RAW_Hosts'!F13 | G20: ='🖥️ RAW_Hosts'!I13 | H20: ='🖥️ RAW_Hosts'!J13 | I20: ='🖥️ RAW_Hosts'!H13 | J20: =IF(ISNUMBER(F20),IF(F20<0.7,"✅ OK",IF(F20<0.85,"⚠️ Warning","🔴 Critique")),IF(VALUE(SUBSTITUTE(F20,"%",""))/100<0.7,"✅ OK",IF(VALUE(SUBSTITUTE(F20,"%",""))/100<0.85,"⚠️ Warning","🔴 Critique"))) | K20: ='🖥️ RAW_Hosts'!G13 | L20: =IFERROR(K20/1024,0) | M20: ='🖥️ RAW_Hosts'!L13 | N20: =IF(K20>0,IF(M20/K20<0.75,"✅ OK",IF(M20/K20<0.90,"⚠️ Warning","🔴 Critique")),"—") | O20: ='🖥️ RAW_Hosts'!K13 | P20: =IF(B20<>"connected","⚠️ Déconnecté",IF(C20="red","🔴 Statut critique",IF(C20="yellow","⚠️ Warning","✅ OK")))
A21: TOTAUX / MOYENNES | H21: =SUM(H11:H20) | I21: =SUM(I11:I20) | K21: =SUM(K11:K20) | L21: =ROUND(SUM(K11:K20)/1024,1) | M21: =SUM(M11:M20) | O21: =SUM(O11:O20)
A23: 📈 CPU & RAM PAR HOST

Sheet 💽 Capacity_Storage
A1: 💽 ANALYSE CAPACITÉ – STOCKAGE
A2: Alimenté automatiquement par 💾 RAW_Datastores | Recalcul instantané
A4: 📊 INDICATEURS GLOBAUX
A5: Cap. Totale (TB) | D5: Cap. Totale (GB) | G5: Espace Libre (GB) | J5: Usage Global | M5: DS critiques
A6: =IFERROR(ROUND(SUM('💾 RAW_Datastores'!F4:F5000),1),0) | D6: =IFERROR(ROUND(SUM('💾 RAW_Datastores'!G4:G5000),0),0) | G6: =IFERROR(ROUND(SUM('💾 RAW_Datastores'!H4:H5000),0),0) | J6: =IFERROR(1-SUM('💾 RAW_Datastores'!H4:H5000)/SUM('💾 RAW_Datastores'!G4:G5000),0) | M6: =COUNTIF('💾 RAW_Datastores'!C4:C5000,"red")+COUNTIF('💾 RAW_Datastores'!C4:C5000,"yellow")
A7: TB total | D7: GB total | G7: GB libres | J7: % utilisé | M7: ⚠️ à traiter
A9: 📋 DÉTAIL PAR DATASTORE
A10: Name | B10: Cluster | C10: Status | D10: Type | E10: DS Cluster | F10: Capacity TB | G10: Capacity (GB) | H10: Free (GB) | I10: FreeSize | J10: Used (GB) | K10: Usage % | L10: Statut | M10: Alerte
A11: ='💾 RAW_Datastores'!A4 | B11: ='💾 RAW_Datastores'!B4 | C11: ='💾 RAW_Datastores'!C4 | D11: ='💾 RAW_Datastores'!D4 | E11: ='💾 RAW_Datastores'!E4 | F11: ='💾 RAW_Datastores'!F4 | G11: ='💾 RAW_Datastores'!G4 | H11: ='💾 RAW_Datastores'!H4 | I11: ='💾 RAW_Datastores'!I4 | J11: =IFERROR(G11-H11,0) | K11: =IFERROR(J11/G11,0) | L11: =IF(K11<0.7,"✅ OK",IF(K11<0.85,"⚠️ Warning","🔴 Critique")) | M11: =IF(C11="red","🔴 Statut rouge",IF(K11>0.90,"🔴 Espace critique",IF(K11>0.80,"⚠️ Surveiller","✅ Normal")))
A12: ='💾 RAW_Datastores'!A5 | B12: ='💾 RAW_Datastores'!B5 | C12: ='💾 RAW_Datastores'!C5 | D12: ='💾 RAW_Datastores'!D5 | E12: ='💾 RAW_Datastores'!E5 | F12: ='💾 RAW_Datastores'!F5 | G12: ='💾 RAW_Datastores'!G5 | H12: ='💾 RAW_Datastores'!H5 | I12: ='💾 RAW_Datastores'!I5 | J12: =IFERROR(G12-H12,0) | K12: =IFERROR(J12/G12,0) | L12: =IF(K12<0.7,"✅ OK",IF(K12<0.85,"⚠️ Warning","🔴 Critique")) | M12: =IF(C12="red","🔴 Statut rouge",IF(K12>0.90,"🔴 Espace critique",IF(K12>0.80,"⚠️ Surveiller","✅ Normal")))
A13: ='💾 RAW_Datastores'!A6 | B13: ='💾 RAW_Datastores'!B6 | C13: ='💾 RAW_Datastores'!C6 | D13: ='💾 RAW_Datastores'!D6 | E13: ='💾 RAW_Datastores'!E6 | F13: ='💾 RAW_Datastores'!F6 | G13: ='💾 RAW_Datastores'!G6 | H13: ='💾 RAW_Datastores'!H6 | I13: ='💾 RAW_Datastores'!I6 | J13: =IFERROR(G13-H13,0) | K13: =IFERROR(J13/G13,0) | L13: =IF(K13<0.7,"✅ OK",IF(K13<0.85,"⚠️ Warning","🔴 Critique")) | M13: =IF(C13="red","🔴 Statut rouge",IF(K13>0.90,"🔴 Espace critique",IF(K13>0.80,"⚠️ Surveiller","✅ Normal")))
A14: ='💾 RAW_Datastores'!A7 | B14: ='💾 RAW_Datastores'!B7 | C14: ='💾 RAW_Datastores'!C7 | D14: ='💾 RAW_Datastores'!D7 | E14: ='💾 RAW_Datastores'!E7 | F14: ='💾 RAW_Datastores'!F7 | G14: ='💾 RAW_Datastores'!G7 | H14: ='💾 RAW_Datastores'!H7 | I14: ='💾 RAW_Datastores'!I7 | J14: =IFERROR(G14-H14,0) | K14: =IFERROR(J14/G14,0) | L14: =IF(K14<0.7,"✅ OK",IF(K14<0.85,"⚠️ Warning","🔴 Critique")) | M14: =IF(C14="red","🔴 Statut rouge",IF(K14>0.90,"🔴 Espace critique",IF(K14>0.80,"⚠️ Surveiller","✅ Normal")))
A15: ='💾 RAW_Datastores'!A8 | B15: ='💾 RAW_Datastores'!B8 | C15: ='💾 RAW_Datastores'!C8 | D15: ='💾 RAW_Datastores'!D8 | E15: ='💾 RAW_Datastores'!E8 | F15: ='💾 RAW_Datastores'!F8 | G15: ='💾 RAW_Datastores'!G8 | H15: ='💾 RAW_Datastores'!H8 | I15: ='💾 RAW_Datastores'!I8 | J15: =IFERROR(G15-H15,0) | K15: =IFERROR(J15/G15,0) | L15: =IF(K15<0.7,"✅ OK",IF(K15<0.85,"⚠️ Warning","🔴 Critique")) | M15: =IF(C15="red","🔴 Statut rouge",IF(K15>0.90,"🔴 Espace critique",IF(K15>0.80,"⚠️ Surveiller","✅ Normal")))
A16: ='💾 RAW_Datastores'!A9 | B16: ='💾 RAW_Datastores'!B9 | C16: ='💾 RAW_Datastores'!C9 | D16: ='💾 RAW_Datastores'!D9 | E16: ='💾 RAW_Datastores'!E9 | F16: ='💾 RAW_Datastores'!F9 | G16: ='💾 RAW_Datastores'!G9 | H16: ='💾 RAW_Datastores'!H9 | I16: ='💾 RAW_Datastores'!I9 | J16: =IFERROR(G16-H16,0) | K16: =IFERROR(J16/G16,0) | L16: =IF(K16<0.7,"✅ OK",IF(K16<0.85,"⚠️ Warning","🔴 Critique")) | M16: =IF(C16="red","🔴 Statut rouge",IF(K16>0.90,"🔴 Espace critique",IF(K16>0.80,"⚠️ Surveiller","✅ Normal")))
A17: ='💾 RAW_Datastores'!A10 | B17: ='💾 RAW_Datastores'!B10 | C17: ='💾 RAW_Datastores'!C10 | D17: ='💾 RAW_Datastores'!D10 | E17: ='💾 RAW_Datastores'!E10 | F17: ='💾 RAW_Datastores'!F10 | G17: ='💾 RAW_Datastores'!G10 | H17: ='💾 RAW_Datastores'!H10 | I17: ='💾 RAW_Datastores'!I10 | J17: =IFERROR(G17-H17,0) | K17: =IFERROR(J17/G17,0) | L17: =IF(K17<0.7,"✅ OK",IF(K17<0.85,"⚠️ Warning","🔴 Critique")) | M17: =IF(C17="red","🔴 Statut rouge",IF(K17>0.90,"🔴 Espace critique",IF(K17>0.80,"⚠️ Surveiller","✅ Normal")))
A18: ='💾 RAW_Datastores'!A11 | B18: ='💾 RAW_Datastores'!B11 | C18: ='💾 RAW_Datastores'!C11 | D18: ='💾 RAW_Datastores'!D11 | E18: ='💾 RAW_Datastores'!E11 | F18: ='💾 RAW_Datastores'!F11 | G18: ='💾 RAW_Datastores'!G11 | H18: ='💾 RAW_Datastores'!H11 | I18: ='💾 RAW_Datastores'!I11 | J18: =IFERROR(G18-H18,0) | K18: =IFERROR(J18/G18,0) | L18: =IF(K18<0.7,"✅ OK",IF(K18<0.85,"⚠️ Warning","🔴 Critique")) | M18: =IF(C18="red","🔴 Statut rouge",IF(K18>0.90,"🔴 Espace critique",IF(K18>0.80,"⚠️ Surveiller","✅ Normal")))
A19: ='💾 RAW_Datastores'!A12 | B19: ='💾 RAW_Datastores'!B12 | C19: ='💾 RAW_Datastores'!C12 | D19: ='💾 RAW_Datastores'!D12 | E19: ='💾 RAW_Datastores'!E12 | F19: ='💾 RAW_Datastores'!F12 | G19: ='💾 RAW_Datastores'!G12 | H19: ='💾 RAW_Datastores'!H12 | I19: ='💾 RAW_Datastores'!I12 | J19: =IFERROR(G19-H19,0) | K19: =IFERROR(J19/G19,0) | L19: =IF(K19<0.7,"✅ OK",IF(K19<0.85,"⚠️ Warning","🔴 Critique")) | M19: =IF(C19="red","🔴 Statut rouge",IF(K19>0.90,"🔴 Espace critique",IF(K19>0.80,"⚠️ Surveiller","✅ Normal")))
A20: ='💾 RAW_Datastores'!A13 | B20: ='💾 RAW_Datastores'!B13 | C20: ='💾 RAW_Datastores'!C13 | D20: ='💾 RAW_Datastores'!D13 | E20: ='💾 RAW_Datastores'!E13 | F20: ='💾 RAW_Datastores'!F13 | G20: ='💾 RAW_Datastores'!G13 | H20: ='💾 RAW_Datastores'!H13 | I20: ='💾 RAW_Datastores'!I13 | J20: =IFERROR(G20-H20,0) | K20: =IFERROR(J20/G20,0) | L20: =IF(K20<0.7,"✅ OK",IF(K20<0.85,"⚠️ Warning","🔴 Critique")) | M20: =IF(C20="red","🔴 Statut rouge",IF(K20>0.90,"🔴 Espace critique",IF(K20>0.80,"⚠️ Surveiller","✅ Normal")))
A21: TOTAUX | F21: =SUM(F11:F20) | G21: =SUM(G11:G20) | H21: =SUM(H11:H20) | J21: =SUM(J11:J20) | K21: =IFERROR(SUM(J11:J20)/SUM(G11:G20),0)
A23: 📊 GRAPHIQUES STOCKAGE

Sheet 🔮 Projections
A1: 🔮 PROJECTIONS DE CAPACITÉ – 12 MOIS
A2: Modifier les cellules BLEUES pour ajuster les hypothèses | Résultats recalculés automatiquement
A4: ⚙️ HYPOTHÈSES DE CROISSANCE (cellules bleues = modifiables)
A5: Croissance VMs / mois | B5: 0.05 | C5: ← % d'augmentation du nb de VMs chaque mois
A6: Croissance CPU consommé / mois | B6: 0.04 | C6: ← % d'augmentation de l'usage CPU chaque mois
A7: Croissance stockage / mois | B7: 0.06 | C7: ← % d'augmentation du stockage utilisé chaque mois
A8: Croissance RAM / mois | B8: 0.04 | C8: ← % d'augmentation de la RAM consommée chaque mois
A9: Seuil alerte CPU (%) | B9: 0.8 | C9: ← Au-delà de ce seuil → Warning CPU
A10: Seuil alerte RAM (%) | B10: 0.85 | C10: ← Au-delà de ce seuil → Warning RAM
A11: Seuil alerte Stockage (%) | B11: 0.85 | C11: ← Au-delà de ce seuil → Warning Stockage
A13: 📅 TABLEAU DE PROJECTION M0 → M+12
A14: Indicateur | B14: M0 (Actuel) | C14: M+1 | D14: M+2 | E14: M+3 | F14: M+4 | G14: M+5 | H14: M+6 | I14: M+7 | J14: M+8 | K14: M+9 | L14: M+10 | M14: M+11 | N14: M+12
A15: ── VMs ──
A16: Nb VMs (total) | B16: =COUNTA('⚡ RAW_VMs'!A4:A5000)-COUNTBLANK('⚡ RAW_VMs'!A4:A5000) | C16: =B16*(1+B5) | D16: =C16*(1+B5) | E16: =D16*(1+B5) | F16: =E16*(1+B5) | G16: =F16*(1+B5) | H16: =G16*(1+B5) | I16: =H16*(1+B5) | J16: =I16*(1+B5) | K16: =J16*(1+B5) | L16: =K16*(1+B5) | M16: =L16*(1+B5) | N16: =M16*(1+B5)
A17: VMs poweredOn | B17: =COUNTIF('⚡ RAW_VMs'!B4:B5000,"poweredOn") | C17: =B17*(1+B5) | D17: =C17*(1+B5) | E17: =D17*(1+B5) | F17: =E17*(1+B5) | G17: =F17*(1+B5) | H17: =G17*(1+B5) | I17: =H17*(1+B5) | J17: =I17*(1+B5) | K17: =J17*(1+B5) | L17: =K17*(1+B5) | M17: =L17*(1+B5) | N17: =M17*(1+B5)
A18: ── CPU ──
A19: CPU consommé moy. (%) | B19: =IFERROR(AVERAGEIF('🖥️ RAW_Hosts'!B4:B5000,"connected",'🖥️ RAW_Hosts'!F4:F5000),0) | C19: =B19*(1+B6) | D19: =C19*(1+B6) | E19: =D19*(1+B6) | F19: =E19*(1+B6) | G19: =F19*(1+B6) | H19: =G19*(1+B6) | I19: =H19*(1+B6) | J19: =I19*(1+B6) | K19: =J19*(1+B6) | L19: =K19*(1+B6) | M19: =L19*(1+B6) | N19: =M19*(1+B6)
A20: Cœurs CPU libres | B20: =SUMIF('🖥️ RAW_Hosts'!B4:B5000,"connected",'🖥️ RAW_Hosts'!J4:J5000) | C20: =B20 | D20: =C20 | E20: =D20 | F20: =E20 | G20: =F20 | H20: =G20 | I20: =H20 | J20: =I20 | ... N20: =M20
A21: Statut CPU | B21: =IF(B19="","",IF(ISNUMBER(B19),IF(B19<B9,"✅ OK",IF(B19<0.95,"⚠️ Warning","🔴 Critique")),"—")) | C21: =IF(C19="","",IF(ISNUMBER(C19),IF(C19<B9,"✅ OK",IF(C19<0.95,"⚠️ Warning","🔴 Critique")),"—")) | D21: =IF(D19="","",IF(ISNUMBER(D19),IF(D19<B9,"✅ OK",IF(D19<0.95,"⚠️ Warning","🔴 Critique")),"—")) | E21: =IF(E19="","",IF(ISNUMBER(E19),IF(E19<B9,"✅ OK",IF(E19<0.95,"⚠️ Warning","🔴 Critique")),"—")) | F21: =IF(F19="","",IF(ISNUMBER(F19),IF(F19<B9,"✅ OK",IF(F19<0.95,"⚠️ Warning","🔴 Critique")),"—")) | G21: =IF(G19="","",IF(ISNUMBER(G19),IF(G19<B9,"✅ OK",IF(G19<0.95,"⚠️ Warning","🔴 Critique")),"—")) | H21: =IF(H19="","",IF(ISNUMBER(H19),IF(H19<B9,"✅ OK",IF(H19<0.95,"⚠️ Warning","🔴 Critique")),"—")) | I21: =IF(I19="","",IF(ISNUMBER(I19),IF(I19<B9,"✅ OK",IF(I19<0.95,"⚠️ Warning","🔴 Critique")),"—")) | J21: =IF(J19="","",IF(ISNUMBER(J19),IF(J19<B9,"✅ OK",IF(J19<0.95,"⚠️ Warning","🔴 Critique")),"—")) | K21: =IF(K19="","",IF(ISNUMBER(K19),IF(K19<B9,"✅ OK",IF(K19<0.95,"⚠️ Warning","🔴 Critique")),"—")) | L21: =IF(L19="","",IF(ISNUMBER(L19),IF(L19<B9,"✅ OK",IF(L19<0.95,"⚠️ Warning","🔴 Critique")),"—")) | M21: =IF(M19="","",IF(ISNUMBER(M19),IF(M19<B9,"✅ OK",IF(M19<0.95,"⚠️ Warning","🔴 Critique")),"—")) | N21: =IF(N19="","",IF(ISNUMBER(N19),IF(N19<B9,"✅ OK",IF(N19<0.95,"⚠️ Warning","🔴 Critique")),"—"))
A22: ── RAM ──
A23: RAM consommée moy. (MB) | B23: =IFERROR(AVERAGEIF('🖥️ RAW_Hosts'!B4:B5000,"connected",'🖥️ RAW_Hosts'!L4:L5000),0) | C23: =B23*(1+B8) | D23: =C23*(1+B8) | E23: =D23*(1+B8) | F23: =E23*(1+B8) | G23: =F23*(1+B8) | H23: =G23*(1+B8) | I23: =H23*(1+B8) | J23: =I23*(1+B8) | K23: =J23*(1+B8) | L23: =K23*(1+B8) | M23: =L23*(1+B8) | N23: =M23*(1+B8)
A24: RAM totale (GB) | B24: =IFERROR(ROUND(SUMIF('🖥️ RAW_Hosts'!B4:B5000,"connected",'🖥️ RAW_Hosts'!G4:G5000)/1024,0),0) | C24: =B24 | D24: =C24 | E24: =D24 | F24: =E24 | G24: =F24 | H24: =G24 | I24: =H24 | J24: =I24 | ... N24: =M24
A25: RAM Usage % | B25: =IFERROR(B23/(B24*1024),0) | C25: =IFERROR(C23/(C24*1024),0) | D25: =IFERROR(D23/(D24*1024),0) | E25: =IFERROR(E23/(E24*1024),0) | F25: =IFERROR(F23/(F24*1024),0) | G25: =IFERROR(G23/(G24*1024),0) | H25: =IFERROR(H23/(H24*1024),0) | I25: =IFERROR(I23/(I24*1024),0) | ... N25: =IFERROR(N23/(N24*1024),0)
A26: Statut RAM | B26: =IF(B25<B10,"✅ OK",IF(B25<0.95,"⚠️ Warning","🔴 Critique")) | C26: =IF(C25<B10,"✅ OK",IF(C25<0.95,"⚠️ Warning","🔴 Critique")) | D26: =IF(D25<B10,"✅ OK",IF(D25<0.95,"⚠️ Warning","🔴 Critique")) | E26: =IF(E25<B10,"✅ OK",IF(E25<0.95,"⚠️ Warning","🔴 Critique")) | F26: =IF(F25<B10,"✅ OK",IF(F25<0.95,"⚠️ Warning","🔴 Critique")) | G26: =IF(G25<B10,"✅ OK",IF(G25<0.95,"⚠️ Warning","🔴 Critique")) | H26: =IF(H25<B10,"✅ OK",IF(H25<0.95,"⚠️ Warning","🔴 Critique")) | I26: =IF(I25<B10,"✅ OK",IF(I25<0.95,"⚠️ Warning","🔴 Critique")) | J26: =IF(J25<B10,"✅ OK",IF(J25<0.95,"⚠️ Warning","🔴 Critique")) | K26: =IF(K25<B10,"✅ OK",IF(K25<0.95,"⚠️ Warning","🔴 Critique")) | L26: =IF(L25<B10,"✅ OK",IF(L25<0.95,"⚠️ Warning","🔴 Critique")) | M26: =IF(M25<B10,"✅ OK",IF(M25<0.95,"⚠️ Warning","🔴 Critique")) | N26: =IF(N25<B10,"✅ OK",IF(N25<0.95,"⚠️ Warning","🔴 Critique"))
A27: ── Stockage ──
A28: Stockage utilisé (GB) | B28: =IFERROR(SUM('💾 RAW_Datastores'!G4:G5000)-SUM('💾 RAW_Datastores'!H4:H5000),0) | C28: =B28*(1+B7) | D28: =C28*(1+B7) | E28: =D28*(1+B7) | F28: =E28*(1+B7) | G28: =F28*(1+B7) | H28: =G28*(1+B7) | I28: =H28*(1+B7) | J28: =I28*(1+B7) | K28: =J28*(1+B7) | L28: =K28*(1+B7) | M28: =L28*(1+B7) | N28: =M28*(1+B7)
A29: Stockage total (GB) | B29: =IFERROR(SUM('💾 RAW_Datastores'!G4:G5000),0) | C29: =B29 | D29: =C29 | E29: =D29 | F29: =E29 | G29: =F29 | H29: =G29 | I29: =H29 | J29: =I29 | ... N29: =M29
A30: Stockage Usage % | B30: =IFERROR(B28/B29,0) | C30: =IFERROR(C28/C29,0) | D30: =IFERROR(D28/D29,0) | E30: =IFERROR(E28/E29,0) | F30: =IFERROR(F28/F29,0) | G30: =IFERROR(G28/G29,0) | H30: =IFERROR(H28/H29,0) | I30: =IFERROR(I28/I29,0) | ... N30: =IFERROR(N28/N29,0)
A31: Statut Stockage | B31: =IF(B30<B11,"✅ OK",IF(B30<0.95,"⚠️ Warning","🔴 Critique")) | C31: =IF(C30<B11,"✅ OK",IF(C30<0.95,"⚠️ Warning","🔴 Critique")) | D31: =IF(D30<B11,"✅ OK",IF(D30<0.95,"⚠️ Warning","🔴 Critique")) | E31: =IF(E30<B11,"✅ OK",IF(E30<0.95,"⚠️ Warning","🔴 Critique")) | F31: =IF(F30<B11,"✅ OK",IF(F30<0.95,"⚠️ Warning","🔴 Critique")) | G31: =IF(G30<B11,"✅ OK",IF(G30<0.95,"⚠️ Warning","🔴 Critique")) | H31: =IF(H30<B11,"✅ OK",IF(H30<0.95,"⚠️ Warning","🔴 Critique")) | I31: =IF(I30<B11,"✅ OK",IF(I30<0.95,"⚠️ Warning","🔴 Critique")) | J31: =IF(J30<B11,"✅ OK",IF(J30<0.95,"⚠️ Warning","🔴 Critique")) | K31: =IF(K30<B11,"✅ OK",IF(K30<0.95,"⚠️ Warning","🔴 Critique")) | L31: =IF(L30<B11,"✅ OK",IF(L30<0.95,"⚠️ Warning","🔴 Critique")) | M31: =IF(M30<B11,"✅ OK",IF(M30<0.95,"⚠️ Warning","🔴 Critique")) | N31: =IF(N30<B11,"✅ OK",IF(N30<0.95,"⚠️ Warning","🔴 Critique"))
A34: 📈 GRAPHIQUES DE PROJECTION

Sheet 📈 Dashboard
B2: 📈 VMWARE CAPACITY PLANNING — DASHBOARD
B4: Généré le 23 March 2026 | vCenter 8.x | Données dynamiques — tableau extensible
B6: 🖥️ COMPUTE
B7: Hosts connectés | F7: Total CPUs | J7: CPU Consommé | N7: Cœurs libres | R7: RAM Totale
B8: =COUNTIF('🖥️ RAW_Hosts'!B4:B5000,"connected") | F8: =SUMIF('🖥️ RAW_Hosts'!B4:B5000,"connected",'🖥️ RAW_Hosts'!H4:H5000) | J8: =IFERROR(AVERAGEIF('🖥️ RAW_Hosts'!B4:B5000,"connected",'🖥️ RAW_Hosts'!F4:F5000),0) | N8: =SUMIF('🖥️ RAW_Hosts'!B4:B5000,"connected",'🖥️ RAW_Hosts'!J4:J5000) | R8: =IFERROR(ROUND(SUMIF('🖥️ RAW_Hosts'!B4:B5000,"connected",'🖥️ RAW_Hosts'!G4:G5000)/1024,0),0)
B9: actifs | F9: CPUs logiques | J9: moy. % used | N9: cores disponibles | R9: GB cluster total
B11: 💽 STOCKAGE & VMs
B12: Total VMs | F12: VMs actives | J12: VMs éteintes | N12: Cap. Stockage | R12: Usage Stockage
B13: =COUNTA('⚡ RAW_VMs'!A4:A5000)-COUNTBLANK('⚡ RAW_VMs'!A4:A5000) | F13: =COUNTIF('⚡ RAW_VMs'!B4:B5000,"poweredOn") | J13: =COUNTIF('⚡ RAW_VMs'!B4:B5000,"poweredOff") | N13: =IFERROR(ROUND(SUM('💾 RAW_Datastores'!F4:F5000),1),0) | R13: =IFERROR(1-SUM('💾 RAW_Datastores'!H4:H5000)/SUM('💾 RAW_Datastores'!G4:G5000),0)
B14: VMs inventaire | F14: poweredOn | J14: poweredOff | N14: TB total | R14: % utilisé global
B16: 🚨 ALERTES INFRASTRUCTURE
B17: Hosts Status rouge | H17: =COUNTIF('🖥️ RAW_Hosts'!C4:C5000,"red")
B18: Hosts Status jaune | H18: =COUNTIF('🖥️ RAW_Hosts'!C4:C5000,"yellow")
B19: Datastores Status rouge | H19: =COUNTIF('💾 RAW_Datastores'!C4:C5000,"red")
B20: VMs Status rouge | H20: =COUNTIF('⚡ RAW_VMs'!C4:C5000,"red")
B21: VMs Status jaune | H21: =COUNTIF('⚡ RAW_VMs'!C4:C5000,"yellow")
B22: DS > 85% utilisé | H22: =COUNTIF('💽 Capacity_Storage'!K11:K20,">0.85")
B24: 📊 VISUALISATIONS
B45: État VM | C45: Count
B46: poweredOn | C46: =COUNTIF('⚡ RAW_VMs'!B4:B5000,"poweredOn")
B47: poweredOff | C47: =COUNTIF('⚡ RAW_VMs'!B4:B5000,"poweredOff")
